Workbook

Sheet Data
A1: Data Pemulusan (Time Series Smoothing) | F1: NIM (2 digit terakhir): | G1: 82
A3: t | B3: Advert (asli) | C3: Advert + NIM | D3: Sales (asli) | E3: Sales + NIM
A4: 1 | B4: 25 | C4: =B4+$G$1 -> 107 | D4: 92.8 | E4: =D4+$G$1 -> 174.8
A5: 2 | B5: 0 | C5: =B5+$G$1 -> 82 | D5: 79.2 | E5: =D5+$G$1 -> 161.2
A6: 3 | B6: 15 | C6: =B6+$G$1 -> 97 | D6: 84.5 | E6: =D6+$G$1 -> 166.5
A7: 4 | B7: 10 | C7: =B7+$G$1 -> 92 | D7: 83 | E7: =D7+$G$1 -> 165.0
A8: 5 | B8: 20 | C8: =B8+$G$1 -> 102 | D8: 88.1 | E8: =D8+$G$1 -> 170.1
A9: 6 | B9: 10 | C9: =B9+$G$1 -> 92 | D9: 83.9 | E9: =D9+$G$1 -> 165.9
A10: 7 | B10: 5 | C10: =B10+$G$1 -> 87 | D10: 79.9 | E10: =D10+$G$1 -> 161.9
A11: 8 | B11: 5 | C11: =B11+$G$1 -> 87 | D11: 81.1 | E11: =D11+$G$1 -> 163.1
A12: 9 | B12: 15 | C12: =B12+$G$1 -> 97 | D12: 86.4 | E12: =D12+$G$1 -> 168.4
A13: 10 | B13: 15 | C13: =B13+$G$1 -> 97 | D13: 86.3 | E13: =D13+$G$1 -> 168.3
A14: 11 | B14: 5 | C14: =B14+$G$1 -> 87 | D14: 81.9 | E14: =D14+$G$1 -> 163.9
A15: 12 | B15: 20 | C15: =B15+$G$1 -> 102 | D15: 90.6 | E15: =D15+$G$1 -> 172.6
... A27: 24 | B27: 5 | C27: =B27+$G$1 -> 87 | D27: 110.9 | E27: =D27+$G$1 -> 192.9

Sheet SMA
A1: Pemulusan SMA (Simple/Single Moving Average) - pencarian orde optimal (m=3,4,5)
A3: ADVERT (data + NIM)
A4: t | B4: Actual | C4: F (m=3) | D4: SE (m=3) | E4: F (m=4) | F4: SE (m=4) | G4: F (m=5) | H4: SE (m=5)
A5: 1 | B5: =Data!C4 -> 107.0
A6: 2 | B6: =Data!C5 -> 82.0
A7: 3 | B7: =Data!C6 -> 97.0
A8: 4 | B8: =Data!C7 -> 92.0 | C8: =AVERAGE(B5:B7) -> 95.33 | D8: =(B8-C8)^2 -> 11.11
A9: 5 | B9: =Data!C8 -> 102.0 | C9: =AVERAGE(B6:B8) -> 90.33 | D9: =(B9-C9)^2 -> 136.11 | E9: =AVERAGE(B5:B8) -> 94.50 | F9: =(B9-E9)^2 -> 56.25
A10: 6 | B10: =Data!C9 -> 92.0 | C10: =AVERAGE(B7:B9) -> 97.00 | D10: =(B10-C10)^2 -> 25.00 | E10: =AVERAGE(B6:B9) -> 93.25 | F10: =(B10-E10)^2 -> 1.56 | G10: =AVERAGE(B5:B9) -> 96.00 | H10: =(B10-G10)^2 -> 16.00
A11: 7 | B11: =Data!C10 -> 87.0 | C11: =AVERAGE(B8:B10) -> 95.33 | D11: =(B11-C11)^2 -> 69.44 | E11: =AVERAGE(B7:B10) -> 95.75 | F11: =(B11-E11)^2 -> 76.56 | G11: =AVERAGE(B6:B10) -> 93.00 | H11: =(B11-G11)^2 -> 36.00
A12: 8 | B12: =Data!C11 -> 87.0 | C12: =AVERAGE(B9:B11) -> 93.67 | D12: =(B12-C12)^2 -> 44.44 | E12: =AVERAGE(B8:B11) -> 93.25 | F12: =(B12-E12)^2 -> 39.06 | G12: =AVERAGE(B7:B11) -> 94.00 | H12: =(B12-G12)^2 -> 49.00
A13: 9 | B13: =Data!C12 -> 97.0 | C13: =AVERAGE(B10:B12) -> 88.67 | D13: =(B13-C13)^2 -> 69.44 | E13: =AVERAGE(B9:B12) -> 92.00 | F13: =(B13-E13)^2 -> 25.00 | G13: =AVERAGE(B8:B12) -> 92.00 | H13: =(B13-G13)^2 -> 25.00
A14: 10 | B14: =Data!C13 -> 97.0 | C14: =AVERAGE(B11:B13) -> 90.33 | D14: =(B14-C14)^2 -> 44.44 | E14: =AVERAGE(B10:B13) -> 90.75 | F14: =(B14-E14)^2 -> 39.06 | G14: =AVERAGE(B9:B13) -> 93.00 | H14: =(B14-G14)^2 -> 16.00
A15: 11 | B15: =Data!C14 -> 87.0 | C15: =AVERAGE(B12:B14) -> 93.67 | D15: =(B15-C15)^2 -> 44.44 | E15: =AVERAGE(B11:B14) -> 92.00 | F15: =(B15-E15)^2 -> 25.00 | G15: =AVERAGE(B10:B14) -> 92.00 | H15: =(B15-G15)^2 -> 25.00
A16: 12 | B16: =Data!C15 -> 102.0 | C16: =AVERAGE(B13:B15) -> 93.67 | D16: =(B16-C16)^2 -> 69.44 | E16: =AVERAGE(B12:B15) -> 92.00 | F16: =(B16-E16)^2 -> 100.00 | G16: =AVERAGE(B11:B15) -> 91.00 | H16: =(B16-G16)^2 -> 121.00
A17: 13 | B17: =Data!C16 -> 97.0 | C17: =AVERAGE(B14:B16) -> 95.33 | D17: =(B17-C17)^2 -> 2.78 | E17: =AVERAGE(B13:B16) -> 95.75 | F17: =(B17-E17)^2 -> 1.56 | G17: =AVERAGE(B12:B16) -> 94.00 | H17: =(B17-G17)^2 -> 9.00
A18: 14 | B18: =Data!C17 -> 87.0 | C18: =AVERAGE(B15:B17) -> 95.33 | D18: =(B18-C18)^2 -> 69.44 | E18: =AVERAGE(B14:B17) -> 95.75 | F18: =(B18-E18)^2 -> 76.56 | G18: =AVERAGE(B13:B17) -> 96.00 | H18: =(B18-G18)^2 -> 81.00
A19: 15 | B19: =Data!C18 -> 92.0 | C19: =AVERAGE(B16:B18) -> 95.33 | D19: =(B19-C19)^2 -> 11.11 | E19: =AVERAGE(B15:B18) -> 93.25 | F19: =(B19-E19)^2 -> 1.56 | G19: =AVERAGE(B14:B18) -> 94.00 | H19: =(B19-G19)^2 -> 4.00
A20: 16 | B20: =Data!C19 -> 107.0 | C20: =AVERAGE(B17:B19) -> 92.00 | D20: =(B20-C20)^2 -> 225.00 | E20: =AVERAGE(B16:B19) -> 94.50 | F20: =(B20-E20)^2 -> 156.25 | G20: =AVERAGE(B15:B19) -> 93.00 | H20: =(B20-G20)^2 -> 196.00
A21: 17 | B21: =Data!C20 -> 97.0 | C21: =AVERAGE(B18:B20) -> 95.33 | D21: =(B21-C21)^2 -> 2.78 | E21: =AVERAGE(B17:B20) -> 95.75 | F21: =(B21-E21)^2 -> 1.56 | G21: =AVERAGE(B16:B20) -> 97.00 | H21: =(B21-G21)^2 -> 0.00
... A28: 24 | B28: =Data!C27 -> 87.0 | C28: =AVERAGE(B25:B27) -> 95.33 | D28: =(B28-C28)^2 -> 69.44 | E28: =AVERAGE(B24:B27) -> 97.00 | F28: =(B28-E28)^2 -> 100.00 | G28: =AVERAGE(B23:B27) -> 97.00 | H28: =(B28-G28)^2 -> 100.00
A30: MSD | D30: =AVERAGE(D5:D28) -> 79.101 | F30: =AVERAGE(F5:F28) -> 64.141 | H30: =AVERAGE(H5:H28) -> 60.105
A31: MAD | D31: =SUMPRODUCT(SQRT(D5:D28))/COUNT(D5:D28) -> 7.619 | F31: =SUMPRODUCT(SQRT(F5:F28))/COUNT(F5:F28) -> 6.563 | H31: =SUMPRODUCT(SQRT(H5:H28))/COUNT(H5:H28) -> 6.526
A32: MAPE (%) | D32: =SUMPRODUCT(SQRT(D5:D28)/B5:B28)/COUNT(D5:D28)*100 -> 8.16 | F32: =SUMPRODUCT(SQRT(F5:F28)/B5:B28)/COUNT(F5:F28)*100 -> 7.06 | H32: =SUMPRODUCT(SQRT(H5:H28)/B5:B28)/COUNT(H5:H28)*100 -> 7.03
A33: Orde terbaik: | B33: =IF(D30=MIN(D30,F30,H30),3,IF(F30=MIN(D30,F30,H30),4,5)) -> 5
A34: MSD terbaik: | B34: =MIN(D30,F30,H30) -> 60.105
A37: SALES (data + NIM)
A38: t | B38: Actual | C38: F (m=3) | D38: SE (m=3) | E38: F (m=4) | F38: SE (m=4) | G38: F (m=5) | H38: SE (m=5)
A39: 1 | B39: =Data!E4 -> 174.8
A40: 2 | B40: =Data!E5 -> 161.2
A41: 3 | B41: =Data!E6 -> 166.5
A42: 4 | B42: =Data!E7 -> 165.0 | C42: =AVERAGE(B39:B41) -> 167.50 | D42: =(B42-C42)^2 -> 6.25
A43: 5 | B43: =Data!E8 -> 170.1 | C43: =AVERAGE(B40:B42) -> 164.23 | D43: =(B43-C43)^2 -> 34.42 | E43: =AVERAGE(B39:B42) -> 166.88 | F43: =(B43-E43)^2 -> 10.40
A44: 6 | B44: =Data!E9 -> 165.9 | C44: =AVERAGE(B41:B43) -> 167.20 | D44: =(B44-C44)^2 -> 1.69 | E44: =AVERAGE(B40:B43) -> 165.70 | F44: =(B44-E44)^2 -> 0.04 | G44: =AVERAGE(B39:B43) -> 167.52 | H44: =(B44-G44)^2 -> 2.62
A45: 7 | B45: =Data!E10 -> 161.9 | C45: =AVERAGE(B42:B44) -> 167.00 | D45: =(B45-C45)^2 -> 26.01 | E45: =AVERAGE(B41:B44) -> 166.88 | F45: =(B45-E45)^2 -> 24.75 | G45: =AVERAGE(B40:B44) -> 165.74 | H45: =(B45-G45)^2 -> 14.75
A46: 8 | B46: =Data!E11 -> 163.1 | C46: =AVERAGE(B43:B45) -> 165.97 | D46: =(B46-C46)^2 -> 8.22 | E46: =AVERAGE(B42:B45) -> 165.73 | F46: =(B46-E46)^2 -> 6.89 | G46: =AVERAGE(B41:B45) -> 165.88 | H46: =(B46-G46)^2 -> 7.73
A47: 9 | B47: =Data!E12 -> 168.4 | C47: =AVERAGE(B44:B46) -> 163.63 | D47: =(B47-C47)^2 -> 22.72 | E47: =AVERAGE(B43:B46) -> 165.25 | F47: =(B47-E47)^2 -> 9.92 | G47: =AVERAGE(B42:B46) -> 165.20 | H47: =(B47-G47)^2 -> 10.24
A48: 10 | B48: =Data!E13 -> 168.3 | C48: =AVERAGE(B45:B47) -> 164.47 | D48: =(B48-C48)^2 -> 14.69 | E48: =AVERAGE(B44:B47) -> 164.83 | F48: =(B48-E48)^2 -> 12.08 | G48: =AVERAGE(B43:B47) -> 165.88 | H48: =(B48-G48)^2 -> 5.86
A49: 11 | B49: =Data!E14 -> 163.9 | C49: =AVERAGE(B46:B48) -> 166.60 | D49: =(B49-C49)^2 -> 7.29 | E49: =AVERAGE(B45:B48) -> 165.43 | F49: =(B49-E49)^2 -> 2.33 | G49: =AVERAGE(B44:B48) -> 165.52 | H49: =(B49-G49)^2 -> 2.62
A50: 12 | B50: =Data!E15 -> 172.6 | C50: =AVERAGE(B47:B49) -> 166.87 | D50: =(B50-C50)^2 -> 32.87 | E50: =AVERAGE(B46:B49) -> 165.93 | F50: =(B50-E50)^2 -> 44.56 | G50: =AVERAGE(B45:B49) -> 165.12 | H50: =(B50-G50)^2 -> 55.95
...

Sheet DMA
A1: Pemulusan DMA (Double Moving Average) - pencarian orde optimal (m=3,4,5)
A4: ADVERT (data + NIM)
A5: ADVERT (data + NIM) - orde m=3
A6: t | B6: Actual | C6: S' (single MA) | D6: S'' (double MA) | E6: a | F6: b | G6: F (t+1)
A7: 1 | B7: =Data!C4 -> 107.00
A8: 2 | B8: =Data!C5 -> 82.00
A9: 3 | B9: =Data!C6 -> 97.00 | C9: =AVERAGE(B7:B9) -> 95.33
A10: 4 | B10: =Data!C7 -> 92.00 | C10: =AVERAGE(B8:B10) -> 90.33
A11: 5 | B11: =Data!C8 -> 102.00 | C11: =AVERAGE(B9:B11) -> 97.00 | D11: =AVERAGE(C9:C11) -> 94.22 | E11: =2*C11-D11 -> 99.78 | F11: =(2/(3-1))*(C11-D11) -> 2.78 | G11: =E11+F11*1 -> 102.56
A12: 6 | B12: =Data!C9 -> 92.00 | C12: =AVERAGE(B10:B12) -> 95.33 | D12: =AVERAGE(C10:C12) -> 94.22 | E12: =2*C12-D12 -> 96.44 | F12: =(2/(3-1))*(C12-D12) -> 1.11 | G12: =E12+F12*1 -> 97.56
A13: 7 | B13: =Data!C10 -> 87.00 | C13: =AVERAGE(B11:B13) -> 93.67 | D13: =AVERAGE(C11:C13) -> 95.33 | E13: =2*C13-D13 -> 92.00 | F13: =(2/(3-1))*(C13-D13) -> -1.67 | G13: =E13+F13*1 -> 90.33
A14: 8 | B14: =Data!C11 -> 87.00 | C14: =AVERAGE(B12:B14) -> 88.67 | D14: =AVERAGE(C12:C14) -> 92.56 | E14: =2*C14-D14 -> 84.78 | F14: =(2/(3-1))*(C14-D14) -> -3.89 | G14: =E14+F14*1 -> 80.89
A15: 9 | B15: =Data!C12 -> 97.00 | C15: =AVERAGE(B13:B15) -> 90.33 | D15: =AVERAGE(C13:C15) -> 90.89 | E15: =2*C15-D15 -> 89.78 | F15: =(2/(3-1))*(C15-D15) -> -0.56 | G15: =E15+F15*1 -> 89.22
A16: 10 | B16: =Data!C13 -> 97.00 | C16: =AVERAGE(B14:B16) -> 93.67 | D16: =AVERAGE(C14:C16) -> 90.89 | E16: =2*C16-D16 -> 96.44 | F16: =(2/(3-1))*(C16-D16) -> 2.78 | G16: =E16+F16*1 -> 99.22
A17: 11 | B17: =Data!C14 -> 87.00 | C17: =AVERAGE(B15:B17) -> 93.67 | D17: =AVERAGE(C15:C17) -> 92.56 | E17: =2*C17-D17 -> 94.78 | F17: =(2/(3-1))*(C17-D17) -> 1.11 | G17: =E17+F17*1 -> 95.89
A18: 12 | B18: =Data!C15 -> 102.00 | C18: =AVERAGE(B16:B18) -> 95.33 | D18: =AVERAGE(C16:C18) -> 94.22 | E18: =2*C18-D18 -> 96.44 | F18: =(2/(3-1))*(C18-D18) -> 1.11 | G18: =E18+F18*1 -> 97.56
A19: 13 | B19: =Data!C16 -> 97.00 | C19: =AVERAGE(B17:B19) -> 95.33 | D19: =AVERAGE(C17:C19) -> 94.78 | E19: =2*C19-D19 -> 95.89 | F19: =(2/(3-1))*(C19-D19) -> 0.56 | G19: =E19+F19*1 -> 96.44
A20: 14 | B20: =Data!C17 -> 87.00 | C20: =AVERAGE(B18:B20) -> 95.33 | D20: =AVERAGE(C18:C20) -> 95.33 | E20: =2*C20-D20 -> 95.33 | F20: =(2/(3-1))*(C20-D20) -> 0.00 | G20: =E20+F20*1 -> 95.33
A21: 15 | B21: =Data!C18 -> 92.00 | C21: =AVERAGE(B19:B21) -> 92.00 | D21: =AVERAGE(C19:C21) -> 94.22 | E21: =2*C21-D21 -> 89.78 | F21: =(2/(3-1))*(C21-D21) -> -2.22 | G21: =E21+F21*1 -> 87.56
A22: 16 | B22: =Data!C19 -> 107.00 | C22: =AVERAGE(B20:B22) -> 95.33 | D22: =AVERAGE(C20:C22) -> 94.22 | E22: =2*C22-D22 -> 96.44 | F22: =(2/(3-1))*(C22-D22) -> 1.11 | G22: =E22+F22*1 -> 97.56
... A30: 24 | B30: =Data!C27 -> 87.00 | C30: =AVERAGE(B28:B30) -> 88.67 | D30: =AVERAGE(C28:C30) -> 95.33 | E30: =2*C30-D30 -> 82.00 | F30: =(2/(3-1))*(C30-D30) -> -6.67 | G30: =E30+F30*1 -> 75.33
A31: MSD | G31: =SUMPRODUCT((B12:B30-G11:G29)^2)/COUNT(G11:G29) -> 142.511
A32: MAD | G32: =SUMPRODUCT(ABS(B12:B30-G11:G29))/COUNT(G11:G29) -> 9.678
A33: MAPE (%) | G33: =SUMPRODUCT(ABS(B12:B30-G11:G29)/B12:B30)/COUNT(G11:G29)*100 -> 10.39
A34: Prediksi t=25: | G34: =G30 -> 75.33
A36: ADVERT (data + NIM) - orde m=4
A37: t | B37: Actual | C37: S' (single MA) | D37: S'' (double MA) | E37: a | F37: b | G37: F (t+1)
A38: 1 | B38: =Data!C4 -> 107.00
A39: 2 | B39: =Data!C5 -> 82.00
A40: 3 | B40: =Data!C6 -> 97.00
A41: 4 | B41: =Data!C7 -> 92.00 | C41: =AVERAGE(B38:B41) -> 94.50
A42: 5 | B42: =Data!C8 -> 102.00 | C42: =AVERAGE(B39:B42) -> 93.25
A43: 6 | B43: =Data!C9 -> 92.00 | C43: =AVERAGE(B40:B43) -> 95.75
A44: 7 | B44: =Data!C10 -> 87.00 | C44: =AVERAGE(B41:B44) -> 93.25 | D44: =AVERAGE(C41:C44) -> 94.19 | E44: =2*C44-D44 -> 92.31 | F44: =(2/(4-1))*(C44-D44) -> -0.63 | G44: =E44+F44*1 -> 91.69
A45: 8 | B45: =Data!C11 -> 87.00 | C45: =AVERAGE(B42:B45) -> 92.00 | D45: =AVERAGE(C42:C45) -> 93.56 | E45: =2*C45-D45 -> 90.44 | F45: =(2/(4-1))*(C45-D45) -> -1.04 | G45: =E45+F45*1 -> 89.40
A46: 9 | B46: =Data!C12 -> 97.00 | C46: =AVERAGE(B43:B46) -> 90.75 | D46: =AVERAGE(C43:C46) -> 92.94 | E46: =2*C46-D46 -> 88.56 | F46: =(2/(4-1))*(C46-D46) -> -1.46 | G46: =E46+F46*1 -> 87.10
A47: 10 | B47: =Data!C13 -> 97.00 | C47: =AVERAGE(B44:B47) -> 92.00 | D47: =AVERAGE(C44:C47) -> 92.00 | E47: =2*C47-D47 -> 92.00 | F47: =(2/(4-1))*(C47-D47) -> 0.00 | G47: =E47+F47*1 -> 92.00
A48: 11 | B48: =Data!C14 -> 87.00 | C48: =AVERAGE(B45:B48) -> 92.00 | D48: =AVERAGE(C45:C48) -> 91.69 | E48: =2*C48-D48 -> 92.31 | F48: =(2/(4-1))*(C48-D48) -> 0.21 | G48: =E48+F48*1 -> 92.52
A49: 12 | B49: =Data!C15 -> 102.00 | C49: =AVERAGE(B46:B49) -> 95.75 | D49: =AVERAGE(C46:C49) -> 92.63 | E49: =2*C49-D49 -> 98.88 | F49: =(2/(4-1))*(C49-D49) -> 2.08 | G49: =E49+F49*1 -> 100.96
A50: 13 | B50: =Data!C16 -> 97.00 | C50: =AVERAGE(B47:B50) -> 95.75 | D50: =AVERAGE(C47:C50) -> 93.88 | E50: =2*C50-D50 -> 97.63 | F50: =(2/(4-1))*(C50-D50) -> 1.25 | G50: =E50+F50*1 -> 98.88
...

Sheet SES
A1: Pemulusan SES (Single Exponential Smoothing) - pencarian alpha optimal (0.1-0.9)
A4: ADVERT (data + NIM)
A5: t | B5: Actual | C5: F (α=0.1) | D5: F (α=0.2) | E5: F (α=0.3) | F5: F (α=0.4) | G5: F (α=0.5) | H5: F (α=0.6) | I5: F (α=0.7) | J5: F (α=0.8) | K5: F (α=0.9)
A6: 1 | B6: =Data!C4 -> 107.00 | C6: =B6 -> 107.00 | D6: =B6 -> 107.00 | E6: =B6 -> 107.00 | F6: =B6 -> 107.00 | G6: =B6 -> 107.00 | H6: =B6 -> 107.00 | I6: =B6 -> 107.00 | J6: =B6 -> 107.00 | K6: =B6 -> 107.00
A7: 2 | B7: =Data!C5 -> 82.00 | C7: =0.1*B6+(1-0.1)*C6 -> 107.00 | D7: =0.2*B6+(1-0.2)*D6 -> 107.00 | E7: =0.3*B6+(1-0.3)*E6 -> 107.00 | F7: =0.4*B6+(1-0.4)*F6 -> 107.00 | G7: =0.5*B6+(1-0.5)*G6 -> 107.00 | H7: =0.6*B6+(1-0.6)*H6 -> 107.00 | I7: =0.7*B6+(1-0.7)*I6 -> 107.00 | J7: =0.8*B6+(1-0.8)*J6 -> 107.00 | K7: =0.9*B6+(1-0.9)*K6 -> 107.00
A8: 3 | B8: =Data!C6 -> 97.00 | C8: =0.1*B7+(1-0.1)*C7 -> 104.50 | D8: =0.2*B7+(1-0.2)*D7 -> 102.00 | E8: =0.3*B7+(1-0.3)*E7 -> 99.50 | F8: =0.4*B7+(1-0.4)*F7 -> 97.00 | G8: =0.5*B7+(1-0.5)*G7 -> 94.50 | H8: =0.6*B7+(1-0.6)*H7 -> 92.00 | I8: =0.7*B7+(1-0.7)*I7 -> 89.50 | J8: =0.8*B7+(1-0.8)*J7 -> 87.00 | K8: =0.9*B7+(1-0.9)*K7 -> 84.50
A9: 4 | B9: =Data!C7 -> 92.00 | C9: =0.1*B8+(1-0.1)*C8 -> 103.75 | D9: =0.2*B8+(1-0.2)*D8 -> 101.00 | E9: =0.3*B8+(1-0.3)*E8 -> 98.75 | F9: =0.4*B8+(1-0.4)*F8 -> 97.00 | G9: =0.5*B8+(1-0.5)*G8 -> 95.75 | H9: =0.6*B8+(1-0.6)*H8 -> 95.00 | I9: =0.7*B8+(1-0.7)*I8 -> 94.75 | J9: =0.8*B8+(1-0.8)*J8 -> 95.00 | K9: =0.9*B8+(1-0.9)*K8 -> 95.75
A10: 5 | B10: =Data!C8 -> 102.00 | C10: =0.1*B9+(1-0.1)*C9 -> 102.58 | D10: =0.2*B9+(1-0.2)*D9 -> 99.20 | E10: =0.3*B9+(1-0.3)*E9 -> 96.73 | F10: =0.4*B9+(1-0.4)*F9 -> 95.00 | G10: =0.5*B9+(1-0.5)*G9 -> 93.88 | H10: =0.6*B9+(1-0.6)*H9 -> 93.20 | I10: =0.7*B9+(1-0.7)*I9 -> 92.83 | J10: =0.8*B9+(1-0.8)*J9 -> 92.60 | K10: =0.9*B9+(1-0.9)*K9 -> 92.38
A11: 6 | B11: =Data!C9 -> 92.00 | C11: =0.1*B10+(1-0.1)*C10 -> 102.52 | D11: =0.2*B10+(1-0.2)*D10 -> 99.76 | E11: =0.3*B10+(1-0.3)*E10 -> 98.31 | F11: =0.4*B10+(1-0.4)*F10 -> 97.80 | G11: =0.5*B10+(1-0.5)*G10 -> 97.94 | H11: =0.6*B10+(1-0.6)*H10 -> 98.48 | I11: =0.7*B10+(1-0.7)*I10 -> 99.25 | J11: =0.8*B10+(1-0.8)*J10 -> 100.12 | K11: =0.9*B10+(1-0.9)*K10 -> 101.04
A12: 7 | B12: =Data!C10 -> 87.00 | C12: =0.1*B11+(1-0.1)*C11 -> 101.47 | D12: =0.2*B11+(1-0.2)*D11 -> 98.21 | E12: =0.3*B11+(1-0.3)*E11 -> 96.42 | F12: =0.4*B11+(1-0.4)*F11 -> 95.48 | G12: =0.5*B11+(1-0.5)*G11 -> 94.97 | H12: =0.6*B11+(1-0.6)*H11 -> 94.59 | I12: =0.7*B11+(1-0.7)*I11 -> 94.17 | J12: =0.8*B11+(1-0.8)*J11 -> 93.62 | K12: =0.9*B11+(1-0.9)*K11 -> 92.90
A13: 8 | B13: =Data!C11 -> 87.00 | C13: =0.1*B12+(1-0.1)*C12 -> 100.02 | D13: =0.2*B12+(1-0.2)*D12 -> 95.97 | E13: =0.3*B12+(1-0.3)*E12 -> 93.59 | F13: =0.4*B12+(1-0.4)*F12 -> 92.09 | G13: =0.5*B12+(1-0.5)*G12 -> 90.98 | H13: =0.6*B12+(1-0.6)*H12 -> 90.04 | I13: =0.7*B12+(1-0.7)*I12 -> 89.15 | J13: =0.8*B12+(1-0.8)*J12 -> 88.32 | K13: =0.9*B12+(1-0.9)*K12 -> 87.59
A14: 9 | B14: =Data!C12 -> 97.00 | C14: =0.1*B13+(1-0.1)*C13 -> 98.72 | D14: =0.2*B13+(1-0.2)*D13 -> 94.17 | E14: =0.3*B13+(1-0.3)*E13 -> 91.61 | F14: =0.4*B13+(1-0.4)*F13 -> 90.05 | G14: =0.5*B13+(1-0.5)*G13 -> 88.99 | H14: =0.6*B13+(1-0.6)*H13 -> 88.21 | I14: =0.7*B13+(1-0.7)*I13 -> 87.65 | J14: =0.8*B13+(1-0.8)*J13 -> 87.26 | K14: =0.9*B13+(1-0.9)*K13 -> 87.06
A15: 10 | B15: =Data!C13 -> 97.00 | C15: =0.1*B14+(1-0.1)*C14 -> 98.55 | D15: =0.2*B14+(1-0.2)*D14 -> 94.74 | E15: =0.3*B14+(1-0.3)*E14 -> 93.23 | F15: =0.4*B14+(1-0.4)*F14 -> 92.83 | G15: =0.5*B14+(1-0.5)*G14 -> 93.00 | H15: =0.6*B14+(1-0.6)*H14 -> 93.49 | I15: =0.7*B14+(1-0.7)*I14 -> 94.19 | J15: =0.8*B14+(1-0.8)*J14 -> 95.05 | K15: =0.9*B14+(1-0.9)*K14 -> 96.01
A16: 11 | B16: =Data!C14 -> 87.00 | C16: =0.1*B15+(1-0.1)*C15 -> 98.39 | D16: =0.2*B15+(1-0.2)*D15 -> 95.19 | E16: =0.3*B15+(1-0.3)*E15 -> 94.36 | F16: =0.4*B15+(1-0.4)*F15 -> 94.50 | G16: =0.5*B15+(1-0.5)*G15 -> 95.00 | H16: =0.6*B15+(1-0.6)*H15 -> 95.59 | I16: =0.7*B15+(1-0.7)*I15 -> 96.16 | J16: =0.8*B15+(1-0.8)*J15 -> 96.61 | K16: =0.9*B15+(1-0.9)*K15 -> 96.90
A17: 12 | B17: =Data!C15 -> 102.00 | C17: =0.1*B16+(1-0.1)*C16 -> 97.25 | D17: =0.2*B16+(1-0.2)*D16 -> 93.55 | E17: =0.3*B16+(1-0.3)*E16 -> 92.15 | F17: =0.4*B16+(1-0.4)*F16 -> 91.50 | G17: =0.5*B16+(1-0.5)*G16 -> 91.00 | H17: =0.6*B16+(1-0.6)*H16 -> 90.44 | I17: =0.7*B16+(1-0.7)*I16 -> 89.75 | J17: =0.8*B16+(1-0.8)*J16 -> 88.92 | K17: =0.9*B16+(1-0.9)*K16 -> 87.99
A18: 13 | B18: =Data!C16 -> 97.00 | C18: =0.1*B17+(1-0.1)*C17 -> 97.73 | D18: =0.2*B17+(1-0.2)*D17 -> 95.24 | E18: =0.3*B17+(1-0.3)*E17 -> 95.11 | F18: =0.4*B17+(1-0.4)*F17 -> 95.70 | G18: =0.5*B17+(1-0.5)*G17 -> 96.50 | H18: =0.6*B17+(1-0.6)*H17 -> 97.38 | I18: =0.7*B17+(1-0.7)*I17 -> 98.32 | J18: =0.8*B17+(1-0.8)*J17 -> 99.38 | K18: =0.9*B17+(1-0.9)*K17 -> 100.60
... A29: 24 | B29: =Data!C27 -> 87.00 | C29: =0.1*B28+(1-0.1)*C28 -> 96.19 | D29: =0.2*B28+(1-0.2)*D28 -> 94.97 | E29: =0.3*B28+(1-0.3)*E28 -> 93.98 | F29: =0.4*B28+(1-0.4)*F28 -> 92.59 | G29: =0.5*B28+(1-0.5)*G28 -> 90.93 | H29: =0.6*B28+(1-0.6)*H28 -> 89.10 | I29: =0.7*B28+(1-0.7)*I28 -> 87.21 | J29: =0.8*B28+(1-0.8)*J28 -> 85.35 | K29: =0.9*B28+(1-0.9)*K28 -> 83.59
B31: alpha -> | C31: 0.1 | D31: 0.2 | E31: 0.3 | F31: 0.4 | G31: 0.5 | H31: 0.6 | I31: 0.7 | J31: 0.8 | K31: 0.9
B32: MSD | C32: =SUMPRODUCT((B7:B29-C7:C29)^2)/COUNT(C7:C29) -> 99.764 | D32: =SUMPRODUCT((B7:B29-D7:D29)^2)/COUNT(D7:D29) -> 87.137 | E32: =SUMPRODUCT((B7:B29-E7:E29)^2)/COUNT(E7:E29) -> 85.378 | F32: =SUMPRODUCT((B7:B29-F7:F29)^2)/COUNT(F7:F29) -> 86.695 | G32: =SUMPRODUCT((B7:B29-G7:G29)^2)/COUNT(G7:G29) -> 89.435 | H32: =SUMPRODUCT((B7:B29-H7:H29)^2)/COUNT(H7:H29) -> 92.999 | I32: =SUMPRODUCT((B7:B29-I7:I29)^2)/COUNT(I7:I29) -> 97.139 | J32: =SUMPRODUCT((B7:B29-J7:J29)^2)/COUNT(J7:J29) -> 101.792 | K32: =SUMPRODUCT((B7:B29-K7:K29)^2)/COUNT(K7:K29) -> 107.025
B33: MAD | C33: =SUMPRODUCT(ABS(B7:B29-C7:C29))/COUNT(C7:C29) -> 7.914 | D33: =SUMPRODUCT(ABS(B7:B29-D7:D29))/COUNT(D7:D29) -> 7.529 | E33: =SUMPRODUCT(ABS(B7:B29-E7:E29))/COUNT(E7:E29) -> 7.448 | F33: =SUMPRODUCT(ABS(B7:B29-F7:F29))/COUNT(F7:F29) -> 7.426 | G33: =SUMPRODUCT(ABS(B7:B29-G7:G29))/COUNT(G7:G29) -> 7.612 | H33: =SUMPRODUCT(ABS(B7:B29-H7:H29))/COUNT(H7:H29) -> 7.856 | I33: =SUMPRODUCT(ABS(B7:B29-I7:I29))/COUNT(I7:I29) -> 8.116 | J33: =SUMPRODUCT(ABS(B7:B29-J7:J29))/COUNT(J7:J29) -> 8.485 | K33: =SUMPRODUCT(ABS(B7:B29-K7:K29))/COUNT(K7:K29) -> 8.829
B34: MAPE (%) | C34: =SUMPRODUCT(ABS(B7:B29-C7:C29)/B7:B29)/COUNT(C7:C29)*100 -> 8.80 | D34: =SUMPRODUCT(ABS(B7:B29-D7:D29)/B7:B29)/COUNT(D7:D29)*100 -> 8.28 | E34: =SUMPRODUCT(ABS(B7:B29-E7:E29)/B7:B29)/COUNT(E7:E29)*100 -> 8.16 | F34: =SUMPRODUCT(ABS(B7:B29-F7:F29)/B7:B29)/COUNT(F7:F29)*100 -> 8.12 | G34: =SUMPRODUCT(ABS(B7:B29-G7:G29)/B7:B29)/COUNT(G7:G29)*100 -> 8.30 | H34: =SUMPRODUCT(ABS(B7:B29-H7:H29)/B7:B29)/COUNT(H7:H29)*100 -> 8.54 | I34: =SUMPRODUCT(ABS(B7:B29-I7:I29)/B7:B29)/COUNT(I7:I29)*100 -> 8.80 | J34: =SUMPRODUCT(ABS(B7:B29-J7:J29)/B7:B29)/COUNT(J7:J29)*100 -> 9.18 | K34: =SUMPRODUCT(ABS(B7:B29-K7:K29)/B7:B29)/COUNT(K7:K29)*100 -> 9.54
A35: Alpha terbaik: | B35: {=INDEX(C31:K31,MATCH(MIN(C32:K32),C32:K32,0))} -> 0.3
A36: MSD terbaik: | B36: =MIN(C32:K32) -> 85.378
A39: SALES (data + NIM)
A40: t | B40: Actual | C40: F (α=0.1) | D40: F (α=0.2) | E40: F (α=0.3) | F40: F (α=0.4) | G40: F (α=0.5) | H40: F (α=0.6) | I40: F (α=0.7) | J40: F (α=0.8) | K40: F (α=0.9)
A41: 1 | B41: =Data!E4 -> 174.80 | C41: =B41 -> 174.80 | D41: =B41 -> 174.80 | E41: =B41 -> 174.80 | F41: =B41 -> 174.80 | G41: =B41 -> 174.80 | H41: =B41 -> 174.80 | I41: =B41 -> 174.80 | J41: =B41 -> 174.80 | K41: =B41 -> 174.80
A42: 2 | B42: =Data!E5 -> 161.20 | C42: =0.1*B41+(1-0.1)*C41 -> 174.80 | D42: =0.2*B41+(1-0.2)*D41 -> 174.80 | E42: =0.3*B41+(1-0.3)*E41 -> 174.80 | F42: =0.4*B41+(1-0.4)*F41 -> 174.80 | G42: =0.5*B41+(1-0.5)*G41 -> 174.80 | H42: =0.6*B41+(1-0.6)*H41 -> 174.80 | I42: =0.7*B41+(1-0.7)*I41 -> 174.80 | J42: =0.8*B41+(1-0.8)*J41 -> 174.80 | K42: =0.9*B41+(1-0.9)*K41 -> 174.80
A43: 3 | B43: =Data!E6 -> 166.50 | C43: =0.1*B42+(1-0.1)*C42 -> 173.44 | D43: =0.2*B42+(1-0.2)*D42 -> 172.08 | E43: =0.3*B42+(1-0.3)*E42 -> 170.72 | F43: =0.4*B42+(1-0.4)*F42 -> 169.36 | G43: =0.5*B42+(1-0.5)*G42 -> 168.00 | H43: =0.6*B42+(1-0.6)*H42 -> 166.64 | I43: =0.7*B42+(1-0.7)*I42 -> 165.28 | J43: =0.8*B42+(1-0.8)*J42 -> 163.92 | K43: =0.9*B42+(1-0.9)*K42 -> 162.56
A44: 4 | B44: =Data!E7 -> 165.00 | C44: =0.1*B43+(1-0.1)*C43 -> 172.75 | D44: =0.2*B43+(1-0.2)*D43 -> 170.96 | E44: =0.3*B43+(1-0.3)*E43 -> 169.45 | F44: =0.4*B43+(1-0.4)*F43 -> 168.22 | G44: =0.5*B43+(1-0.5)*G43 -> 167.25 | H44: =0.6*B43+(1-0.6)*H43 -> 166.56 | I44: =0.7*B43+(1-0.7)*I43 -> 166.13 | J44: =0.8*B43+(1-0.8)*J43 -> 165.98 | K44: =0.9*B43+(1-0.9)*K43 -> 166.11
A45: 5 | B45: =Data!E8 -> 170.10 | C45: =0.1*B44+(1-0.1)*C44 -> 171.97 | D45: =0.2*B44+(1-0.2)*D44 -> 169.77 | E45: =0.3*B44+(1-0.3)*E44 -> 168.12 | F45: =0.4*B44+(1-0.4)*F44 -> 166.93 | G45: =0.5*B44+(1-0.5)*G44 -> 166.13 | H45: =0.6*B44+(1-0.6)*H44 -> 165.62 | I45: =0.7*B44+(1-0.7)*I44 -> 165.34 | J45: =0.8*B44+(1-0.8)*J44 -> 165.20 | K45: =0.9*B44+(1-0.9)*K44 -> 165.11
A46: 6 | B46: =Data!E9 -> 165.90 | C46: =0.1*B45+(1-0.1)*C45 -> 171.78 | D46: =0.2*B45+(1-0.2)*D45 -> 169.84 | E46: =0.3*B45+(1-0.3)*E45 -> 168.71 | F46: =0.4*B45+(1-0.4)*F45 -> 168.20 | G46: =0.5*B45+(1-0.5)*G45 -> 168.11 | H46: =0.6*B45+(1-0.6)*H45 -> 168.31 | I46: =0.7*B45+(1-0.7)*I45 -> 168.67 | J46: =0.8*B45+(1-0.8)*J45 -> 169.12 | K46: =0.9*B45+(1-0.9)*K45 -> 169.60
A47: 7 | B47: =Data!E10 -> 161.90 | C47: =0.1*B46+(1-0.1)*C46 -> 171.20 | D47: =0.2*B46+(1-0.2)*D46 -> 169.05 | E47: =0.3*B46+(1-0.3)*E46 -> 167.87 | F47: =0.4*B46+(1-0.4)*F46 -> 167.28 | G47: =0.5*B46+(1-0.5)*G46 -> 167.01 | H47: =0.6*B46+(1-0.6)*H46 -> 166.86 | I47: =0.7*B46+(1-0.7)*I46 -> 166.73 | J47: =0.8*B46+(1-0.8)*J46 -> 166.54 | K47: =0.9*B46+(1-0.9)*K46 -> 166.27
A48: 8 | B48: =Data!E11 -> 163.10 | C48: =0.1*B47+(1-0.1)*C47 -> 170.27 | D48: =0.2*B47+(1-0.2)*D47 -> 167.62 | E48: =0.3*B47+(1-0.3)*E47 -> 166.08 | F48: =0.4*B47+(1-0.4)*F47 -> 165.13 | G48: =0.5*B47+(1-0.5)*G47 -> 164.45 | H48: =0.6*B47+(1-0.6)*H47 -> 163.89 | I48: =0.7*B47+(1-0.7)*I47 -> 163.35 | J48: =0.8*B47+(1-0.8)*J47 -> 162.83 | K48: =0.9*B47+(1-0.9)*K47 -> 162.34
A49: 9 | B49: =Data!E12 -> 168.40 | C49: =0.1*B48+(1-0.1)*C48 -> 169.55 | D49: =0.2*B48+(1-0.2)*D48 -> 166.72 | E49: =0.3*B48+(1-0.3)*E48 -> 165.18 | F49: =0.4*B48+(1-0.4)*F48 -> 164.32 | G49: =0.5*B48+(1-0.5)*G48 -> 163.78 | H49: =0.6*B48+(1-0.6)*H48 -> 163.41 | I49: =0.7*B48+(1-0.7)*I48 -> 163.17 | J49: =0.8*B48+(1-0.8)*J48 -> 163.05 | K49: =0.9*B48+(1-0.9)*K48 -> 163.02
A50: 10 | B50: =Data!E13 -> 168.30 | C50: =0.1*B49+(1-0.1)*C49 -> 169.43 | D50: =0.2*B49+(1-0.2)*D49 -> 167.05 | E50: =0.3*B49+(1-0.3)*E49 -> 166.15 | F50: =0.4*B49+(1-0.4)*F49 -> 165.95 | G50: =0.5*B49+(1-0.5)*G49 -> 166.09 | H50: =0.6*B49+(1-0.6)*H49 -> 166.41 | I50: =0.7*B49+(1-0.7)*I49 -> 166.83 | J50: =0.8*B49+(1-0.8)*J49 -> 167.33 | K50: =0.9*B49+(1-0.9)*K49 -> 167.86
A51: 11 | B51: =Data!E14 -> 163.90 | C51: =0.1*B50+(1-0.1)*C50 -> 169.32 | D51: =0.2*B50+(1-0.2)*D50 -> 167.30 | E51: =0.3*B50+(1-0.3)*E50 -> 166.79 | F51: =0.4*B50+(1-0.4)*F50 -> 166.89 | G51: =0.5*B50+(1-0.5)*G50 -> 167.19 | H51: =0.6*B50+(1-0.6)*H50 -> 167.54 | I51: =0.7*B50+(1-0.7)*I50 -> 167.86 | J51: =0.8*B50+(1-0.8)*J50 -> 168.11 | K51: =0.9*B50+(1-0.9)*K50 -> 168.26
A52: 12 | B52: =Data!E15 -> 172.60 | C52: =0.1*B51+(1-0.1)*C51 -> 168.78 | D52: =0.2*B51+(1-0.2)*D51 -> 166.62 | E52: =0.3*B51+(1-0.3)*E51 -> 165.93 | F52: =0.4*B51+(1-0.4)*F51 -> 165.69 | G52: =0.5*B51+(1-0.5)*G51 -> 165.55 | H52: =0.6*B51+(1-0.6)*H51 -> 165.36 | I52: =0.7*B51+(1-0.7)*I51 -> 165.09 | J52: =0.8*B51+(1-0.8)*J51 -> 164.74 | K52: =0.9*B51+(1-0.9)*K51 -> 164.34
A53: 13 | B53: =Data!E16 -> 173.40 | C53: =0.1*B52+(1-0.1)*C52 -> 169.16 | D53: =0.2*B52+(1-0.2)*D52 -> 167.82 | E53: =0.3*B52+(1-0.3)*E52 -> 167.93 | F53: =0.4*B52+(1-0.4)*F52 -> 168.46 | G53: =0.5*B52+(1-0.5)*G52 -> 169.07 | H53: =0.6*B52+(1-0.6)*H52 -> 169.70 | I53: =0.7*B52+(1-0.7)*I52 -> 170.35 | J53: =0.8*B52+(1-0.8)*J52 -> 171.03 | K53: =0.9*B52+(1-0.9)*K52 -> 171.77
... A64: 24 | B64: =Data!E27 -> 192.90 | C64: =0.1*B63+(1-0.1)*C63 -> 181.44 | D64: =0.2*B63+(1-0.2)*D63 -> 187.05 | E64: =0.3*B63+(1-0.3)*E63 -> 189.61 | F64: =0.4*B63+(1-0.4)*F63 -> 190.48 | G64: =0.5*B63+(1-0.5)*G63 -> 190.52 | H64: =0.6*B63+(1-0.6)*H63 -> 190.15 | I64: =0.7*B63+(1-0.7)*I63 -> 189.56 | J64: =0.8*B63+(1-0.8)*J63 -> 188.89 | K64: =0.9*B63+(1-0.9)*K63 -> 188.18
B66: alpha -> | C66: 0.1 | D66: 0.2 | E66: 0.3 | F66: 0.4 | G66: 0.5 | H66: 0.6 | I66: 0.7 | J66: 0.8 | K66: 0.9
...

Sheet DES
A1: Pemulusan DES Brown (Double Exponential Smoothing, 1 parameter) - pencarian alpha optimal (0.1-0.9)
A5: ADVERT (data + NIM)
A6: t | B6: Actual | C6: S' (α=0.1) | D6: S'' (α=0.1) | E6: F (α=0.1) | F6: S' (α=0.2) | G6: S'' (α=0.2) | H6: F (α=0.2) | I6: S' (α=0.3) | J6: S'' (α=0.3) | K6: F (α=0.3) | L6: S' (α=0.4) | M6: S'' (α=0.4) | N6: F (α=0.4) | O6: S' (α=0.5) | P6: S'' (α=0.5) | Q6: F (α=0.5) | R6: S' (α=0.6) | S6: S'' (α=0.6) | T6: F (α=0.6) | U6: S' (α=0.7) | V6: S'' (α=0.7) | W6: F (α=0.7) | X6: S' (α=0.8) | Y6: S'' (α=0.8) | Z6: F (α=0.8) | AA6: S' (α=0.9) | AB6: S'' (α=0.9) | AC6: F (α=0.9)
A7: 1 | B7: =Data!C4 -> 107.00 | C7: =B7 -> 107.00 | D7: =B7 -> 107.00 | E7: =2*C7-D7+(0.1/(1-0.1))*(C7-D7) -> 107.00 | F7: =B7 -> 107.00 | G7: =B7 -> 107.00 | H7: =2*F7-G7+(0.2/(1-0.2))*(F7-G7) -> 107.00 | I7: =B7 -> 107.00 | J7: =B7 -> 107.00 | K7: =2*I7-J7+(0.3/(1-0.3))*(I7-J7) -> 107.00 | L7: =B7 -> 107.00 | M7: =B7 -> 107.00 | N7: =2*L7-M7+(0.4/(1-0.4))*(L7-M7) -> 107.00 | O7: =B7 -> 107.00 | P7: =B7 -> 107.00 | Q7: =2*O7-P7+(0.5/(1-0.5))*(O7-P7) -> 107.00 | R7: =B7 -> 107.00 | S7: =B7 -> 107.00 | T7: =2*R7-S7+(0.6/(1-0.6))*(R7-S7) -> 107.00 | U7: =B7 -> 107.00 | V7: =B7 -> 107.00 | W7: =2*U7-V7+(0.7/(1-0.7))*(U7-V7) -> 107.00 | X7: =B7 -> 107.00 | Y7: =B7 -> 107.00 | Z7: =2*X7-Y7+(0.8/(1-0.8))*(X7-Y7) -> 107.00 | AA7: =B7 -> 107.00 | AB7: =B7 -> 107.00 | AC7: =2*AA7-AB7+(0.9/(1-0.9))*(AA7-AB7) -> 107.00
A8: 2 | B8: =Data!C5 -> 82.00 | C8: =0.1*B8+(1-0.1)*C7 -> 104.50 | D8: =0.1*C8+(1-0.1)*D7 -> 106.75 | E8: =2*C8-D8+(0.1/(1-0.1))*(C8-D8) -> 102.00 | F8: =0.2*B8+(1-0.2)*F7 -> 102.00 | G8: =0.2*F8+(1-0.2)*G7 -> 106.00 | H8: =2*F8-G8+(0.2/(1-0.2))*(F8-G8) -> 97.00 | I8: =0.3*B8+(1-0.3)*I7 -> 99.50 | J8: =0.3*I8+(1-0.3)*J7 -> 104.75 | K8: =2*I8-J8+(0.3/(1-0.3))*(I8-J8) -> 92.00 | L8: =0.4*B8+(1-0.4)*L7 -> 97.00 | M8: =0.4*L8+(1-0.4)*M7 -> 103.00 | N8: =2*L8-M8+(0.4/(1-0.4))*(L8-M8) -> 87.00 | O8: =0.5*B8+(1-0.5)*O7 -> 94.50 | P8: =0.5*O8+(1-0.5)*P7 -> 100.75 | Q8: =2*O8-P8+(0.5/(1-0.5))*(O8-P8) -> 82.00 | R8: =0.6*B8+(1-0.6)*R7 -> 92.00 | S8: =0.6*R8+(1-0.6)*S7 -> 98.00 | T8: =2*R8-S8+(0.6/(1-0.6))*(R8-S8) -> 77.00 | U8: =0.7*B8+(1-0.7)*U7 -> 89.50 | V8: =0.7*U8+(1-0.7)*V7 -> 94.75 | W8: =2*U8-V8+(0.7/(1-0.7))*(U8-V8) -> 72.00 | X8: =0.8*B8+(1-0.8)*X7 -> 87.00 | Y8: =0.8*X8+(1-0.8)*Y7 -> 91.00 | Z8: =2*X8-Y8+(0.8/(1-0.8))*(X8-Y8) -> 67.00 | AA8: =0.9*B8+(1-0.9)*AA7 -> 84.50 | AB8: =0.9*AA8+(1-0.9)*AB7 -> 86.75 | AC8: =2*AA8-AB8+(0.9/(1-0.9))*(AA8-AB8) -> 62.00
A9: 3 | B9: =Data!C6 -> 97.00 | C9: =0.1*B9+(1-0.1)*C8 -> 103.75 | D9: =0.1*C9+(1-0.1)*D8 -> 106.45 | E9: =2*C9-D9+(0.1/(1-0.1))*(C9-D9) -> 100.75 | F9: =0.2*B9+(1-0.2)*F8 -> 101.00 | G9: =0.2*F9+(1-0.2)*G8 -> 105.00 | H9: =2*F9-G9+(0.2/(1-0.2))*(F9-G9) -> 96.00 | I9: =0.3*B9+(1-0.3)*I8 -> 98.75 | J9: =0.3*I9+(1-0.3)*J8 -> 102.95 | K9: =2*I9-J9+(0.3/(1-0.3))*(I9-J9) -> 92.75 | L9: =0.4*B9+(1-0.4)*L8 -> 97.00 | M9: =0.4*L9+(1-0.4)*M8 -> 100.60 | N9: =2*L9-M9+(0.4/(1-0.4))*(L9-M9) -> 91.00 | O9: =0.5*B9+(1-0.5)*O8 -> 95.75 | P9: =0.5*O9+(1-0.5)*P8 -> 98.25 | Q9: =2*O9-P9+(0.5/(1-0.5))*(O9-P9) -> 90.75 | R9: =0.6*B9+(1-0.6)*R8 -> 95.00 | S9: =0.6*R9+(1-0.6)*S8 -> 96.20 | T9: =2*R9-S9+(0.6/(1-0.6))*(R9-S9) -> 92.00 | U9: =0.7*B9+(1-0.7)*U8 -> 94.75 | V9: =0.7*U9+(1-0.7)*V8 -> 94.75 | W9: =2*U9-V9+(0.7/(1-0.7))*(U9-V9) -> 94.75 | X9: =0.8*B9+(1-0.8)*X8 -> 95.00 | Y9: =0.8*X9+(1-0.8)*Y8 -> 94.20 | Z9: =2*X9-Y9+(0.8/(1-0.8))*(X9-Y9) -> 99.00 | AA9: =0.9*B9+(1-0.9)*AA8 -> 95.75 | AB9: =0.9*AA9+(1-0.9)*AB8 -> 94.85 | AC9: =2*AA9-AB9+(0.9/(1-0.9))*(AA9-AB9) -> 104.75
A10: 4 | B10: =Data!C7 -> 92.00 | C10: =0.1*B10+(1-0.1)*C9 -> 102.58 | D10: =0.1*C10+(1-0.1)*D9 -> 106.06 | E10: =2*C10-D10+(0.1/(1-0.1))*(C10-D10) -> 98.70 | F10: =0.2*B10+(1-0.2)*F9 -> 99.20 | G10: =0.2*F10+(1-0.2)*G9 -> 103.84 | H10: =2*F10-G10+(0.2/(1-0.2))*(F10-G10) -> 93.40 | I10: =0.3*B10+(1-0.3)*I9 -> 96.73 | J10: =0.3*I10+(1-0.3)*J9 -> 101.08 | K10: =2*I10-J10+(0.3/(1-0.3))*(I10-J10) -> 90.50 | L10: =0.4*B10+(1-0.4)*L9 -> 95.00 | M10: =0.4*L10+(1-0.4)*M9 -> 98.36 | N10: =2*L10-M10+(0.4/(1-0.4))*(L10-M10) -> 89.40 | O10: =0.5*B10+(1-0.5)*O9 -> 93.88 | P10: =0.5*O10+(1-0.5)*P9 -> 96.06 | Q10: =2*O10-P10+(0.5/(1-0.5))*(O10-P10) -> 89.50 | R10: =0.6*B10+(1-0.6)*R9 -> 93.20 | S10: =0.6*R10+(1-0.6)*S9 -> 94.40 | T10: =2*R10-S10+(0.6/(1-0.6))*(R10-S10) -> 90.20 | U10: =0.7*B10+(1-0.7)*U9 -> 92.83 | V10: =0.7*U10+(1-0.7)*V9 -> 93.40 | W10: =2*U10-V10+(0.7/(1-0.7))*(U10-V10) -> 90.90 | X10: =0.8*B10+(1-0.8)*X9 -> 92.60 | Y10: =0.8*X10+(1-0.8)*Y9 -> 92.92 | Z10: =2*X10-Y10+(0.8/(1-0.8))*(X10-Y10) -> 91.00 | AA10: =0.9*B10+(1-0.9)*AA9 -> 92.38 | AB10: =0.9*AA10+(1-0.9)*AB9 -> 92.62 | AC10: =2*AA10-AB10+(0.9/(1-0.9))*(AA10-AB10) -> 89.90
A11: 5 | B11: =Data!C8 -> 102.00 | C11: =0.1*B11+(1-0.1)*C10 -> 102.52 | D11: =0.1*C11+(1-0.1)*D10 -> 105.71 | E11: =2*C11-D11+(0.1/(1-0.1))*(C11-D11) -> 98.97 | F11: =0.2*B11+(1-0.2)*F10 -> 99.76 | G11: =0.2*F11+(1-0.2)*G10 -> 103.02 | H11: =2*F11-G11+(0.2/(1-0.2))*(F11-G11) -> 95.68 | I11: =0.3*B11+(1-0.3)*I10 -> 98.31 | J11: =0.3*I11+(1-0.3)*J10 -> 100.25 | K11: =2*I11-J11+(0.3/(1-0.3))*(I11-J11) -> 95.53 | L11: =0.4*B11+(1-0.4)*L10 -> 97.80 | M11: =0.4*L11+(1-0.4)*M10 -> 98.14 | N11: =2*L11-M11+(0.4/(1-0.4))*(L11-M11) -> 97.24 | O11: =0.5*B11+(1-0.5)*O10 -> 97.94 | P11: =0.5*O11+(1-0.5)*P10 -> 97.00 | Q11: =2*O11-P11+(0.5/(1-0.5))*(O11-P11) -> 99.81 | R11: =0.6*B11+(1-0.6)*R10 -> 98.48 | S11: =0.6*R11+(1-0.6)*S10 -> 96.85 | T11: =2*R11-S11+(0.6/(1-0.6))*(R11-S11) -> 102.56 | U11: =0.7*B11+(1-0.7)*U10 -> 99.25 | V11: =0.7*U11+(1-0.7)*V10 -> 97.49 | W11: =2*U11-V11+(0.7/(1-0.7))*(U11-V11) -> 105.09 | X11: =0.8*B11+(1-0.8)*X10 -> 100.12 | Y11: =0.8*X11+(1-0.8)*Y10 -> 98.68 | Z11: =2*X11-Y11+(0.8/(1-0.8))*(X11-Y11) -> 107.32 | AA11: =0.9*B11+(1-0.9)*AA10 -> 101.04 | AB11: =0.9*AA11+(1-0.9)*AB10 -> 100.20 | AC11: =2*AA11-AB11+(0.9/(1-0.9))*(AA11-AB11) -> 109.45
A12: 6 | B12: =Data!C9 -> 92.00 | C12: =0.1*B12+(1-0.1)*C11 -> 101.47 | D12: =0.1*C12+(1-0.1)*D11 -> 105.28 | E12: =2*C12-D12+(0.1/(1-0.1))*(C12-D12) -> 97.22 | F12: =0.2*B12+(1-0.2)*F11 -> 98.21 | G12: =0.2*F12+(1-0.2)*G11 -> 102.06 | H12: =2*F12-G12+(0.2/(1-0.2))*(F12-G12) -> 93.39 | I12: =0.3*B12+(1-0.3)*I11 -> 96.42 | J12: =0.3*I12+(1-0.3)*J11 -> 99.10 | K12: =2*I12-J12+(0.3/(1-0.3))*(I12-J12) -> 92.58 | L12: =0.4*B12+(1-0.4)*L11 -> 95.48 | M12: =0.4*L12+(1-0.4)*M11 -> 97.07 | N12: =2*L12-M12+(0.4/(1-0.4))*(L12-M12) -> 92.82 | O12: =0.5*B12+(1-0.5)*O11 -> 94.97 | P12: =0.5*O12+(1-0.5)*P11 -> 95.98 | Q12: =2*O12-P12+(0.5/(1-0.5))*(O12-P12) -> 92.94 | R12: =0.6*B12+(1-0.6)*R11 -> 94.59 | S12: =0.6*R12+(1-0.6)*S11 -> 95.49 | T12: =2*R12-S12+(0.6/(1-0.6))*(R12-S12) -> 92.34 | U12: =0.7*B12+(1-0.7)*U11 -> 94.17 | V12: =0.7*U12+(1-0.7)*V11 -> 95.17 | W12: =2*U12-V12+(0.7/(1-0.7))*(U12-V12) -> 90.85 | X12: =0.8*B12+(1-0.8)*X11 -> 93.62 | Y12: =0.8*X12+(1-0.8)*Y11 -> 94.64 | Z12: =2*X12-Y12+(0.8/(1-0.8))*(X12-Y12) -> 88.57 | AA12: =0.9*B12+(1-0.9)*AA11 -> 92.90 | AB12: =0.9*AA12+(1-0.9)*AB11 -> 93.63 | AC12: =2*AA12-AB12+(0.9/(1-0.9))*(AA12-AB12) -> 85.61
A13: 7 | B13: =Data!C10 -> 87.00 | C13: =0.1*B13+(1-0.1)*C12 -> 100.02 | D13: =0.1*C13+(1-0.1)*D12 -> 104.76 | E13: =2*C13-D13+(0.1/(1-0.1))*(C13-D13) -> 94.75 | F13: =0.2*B13+(1-0.2)*F12 -> 95.97 | G13: =0.2*F13+(1-0.2)*G12 -> 100.84 | H13: =2*F13-G13+(0.2/(1-0.2))*(F13-G13) -> 89.87 | I13: =0.3*B13+(1-0.3)*I12 -> 93.59 | J13: =0.3*I13+(1-0.3)*J12 -> 97.45 | K13: =2*I13-J13+(0.3/(1-0.3))*(I13-J13) -> 88.08 | L13: =0.4*B13+(1-0.4)*L12 -> 92.09 | M13: =0.4*L13+(1-0.4)*M12 -> 95.08 | N13: =2*L13-M13+(0.4/(1-0.4))*(L13-M13) -> 87.10 | O13: =0.5*B13+(1-0.5)*O12 -> 90.98 | P13: =0.5*O13+(1-0.5)*P12 -> 93.48 | Q13: =2*O13-P13+(0.5/(1-0.5))*(O13-P13) -> 85.98 | R13: =0.6*B13+(1-0.6)*R12 -> 90.04 | S13: =0.6*R13+(1-0.6)*S12 -> 92.22 | T13: =2*R13-S13+(0.6/(1-0.6))*(R13-S13) -> 84.58 | U13: =0.7*B13+(1-0.7)*U12 -> 89.15 | V13: =0.7*U13+(1-0.7)*V12 -> 90.96 | W13: =2*U13-V13+(0.7/(1-0.7))*(U13-V13) -> 83.13 | X13: =0.8*B13+(1-0.8)*X12 -> 88.32 | Y13: =0.8*X13+(1-0.8)*Y12 -> 89.59 | Z13: =2*X13-Y13+(0.8/(1-0.8))*(X13-Y13) -> 82.01 | AA13: =0.9*B13+(1-0.9)*AA12 -> 87.59 | AB13: =0.9*AA13+(1-0.9)*AB12 -> 88.19 | AC13: =2*AA13-AB13+(0.9/(1-0.9))*(AA13-AB13) -> 81.55
A14: 8 | B14: =Data!C11 -> 87.00 | C14: =0.1*B14+(1-0.1)*C13 -> 98.72 | D14: =0.1*C14+(1-0.1)*D13 -> 104.15 | E14: =2*C14-D14+(0.1/(1-0.1))*(C14-D14) -> 92.68 | F14: =0.2*B14+(1-0.2)*F13 -> 94.17 | G14: =0.2*F14+(1-0.2)*G13 -> 99.51 | H14: =2*F14-G14+(0.2/(1-0.2))*(F14-G14) -> 87.50 | I14: =0.3*B14+(1-0.3)*I13 -> 91.61 | J14: =0.3*I14+(1-0.3)*J13 -> 95.70 | K14: =2*I14-J14+(0.3/(1-0.3))*(I14-J14) -> 85.78 | L14: =0.4*B14+(1-0.4)*L13 -> 90.05 | M14: =0.4*L14+(1-0.4)*M13 -> 93.07 | N14: =2*L14-M14+(0.4/(1-0.4))*(L14-M14) -> 85.03 | O14: =0.5*B14+(1-0.5)*O13 -> 88.99 | P14: =0.5*O14+(1-0.5)*P13 -> 91.24 | Q14: =2*O14-P14+(0.5/(1-0.5))*(O14-P14) -> 84.50 | R14: =0.6*B14+(1-0.6)*R13 -> 88.21 | S14: =0.6*R14+(1-0.6)*S13 -> 89.82 | T14: =2*R14-S14+(0.6/(1-0.6))*(R14-S14) -> 84.21 | U14: =0.7*B14+(1-0.7)*U13 -> 87.65 | V14: =0.7*U14+(1-0.7)*V13 -> 88.64 | W14: =2*U14-V14+(0.7/(1-0.7))*(U14-V14) -> 84.33 | X14: =0.8*B14+(1-0.8)*X13 -> 87.26 | Y14: =0.8*X14+(1-0.8)*Y13 -> 87.73 | Z14: =2*X14-Y14+(0.8/(1-0.8))*(X14-Y14) -> 84.94 | AA14: =0.9*B14+(1-0.9)*AA13 -> 87.06 | AB14: =0.9*AA14+(1-0.9)*AB13 -> 87.17 | AC14: =2*AA14-AB14+(0.9/(1-0.9))*(AA14-AB14) -> 85.92
A15: 9 | B15: =Data!C12 -> 97.00 | C15: =0.1*B15+(1-0.1)*C14 -> 98.55 | D15: =0.1*C15+(1-0.1)*D14 -> 103.59 | E15: =2*C15-D15+(0.1/(1-0.1))*(C15-D15) -> 92.94 | F15: =0.2*B15+(1-0.2)*F14 -> 94.74 | G15: =0.2*F15+(1-0.2)*G14 -> 98.55 | H15: =2*F15-G15+(0.2/(1-0.2))*(F15-G15) -> 89.97 | I15: =0.3*B15+(1-0.3)*I14 -> 93.23 | J15: =0.3*I15+(1-0.3)*J14 -> 94.96 | K15: =2*I15-J15+(0.3/(1-0.3))*(I15-J15) -> 90.76 | L15: =0.4*B15+(1-0.4)*L14 -> 92.83 | M15: =0.4*L15+(1-0.4)*M14 -> 92.97 | N15: =2*L15-M15+(0.4/(1-0.4))*(L15-M15) -> 92.59 | O15: =0.5*B15+(1-0.5)*O14 -> 93.00 | P15: =0.5*O15+(1-0.5)*P14 -> 92.12 | Q15: =2*O15-P15+(0.5/(1-0.5))*(O15-P15) -> 94.75 | R15: =0.6*B15+(1-0.6)*R14 -> 93.49 | S15: =0.6*R15+(1-0.6)*S14 -> 92.02 | T15: =2*R15-S15+(0.6/(1-0.6))*(R15-S15) -> 97.16 | U15: =0.7*B15+(1-0.7)*U14 -> 94.19 | V15: =0.7*U15+(1-0.7)*V14 -> 92.53 | W15: =2*U15-V15+(0.7/(1-0.7))*(U15-V15) -> 99.75 | X15: =0.8*B15+(1-0.8)*X14 -> 95.05 | Y15: =0.8*X15+(1-0.8)*Y14 -> 93.59 | Z15: =2*X15-Y15+(0.8/(1-0.8))*(X15-Y15) -> 102.38 | AA15: =0.9*B15+(1-0.9)*AA14 -> 96.01 | AB15: =0.9*AA15+(1-0.9)*AB14 -> 95.12 | AC15: =2*AA15-AB15+(0.9/(1-0.9))*(AA15-AB15) -> 104.84
A16: 10 | B16: =Data!C13 -> 97.00 | C16: =0.1*B16+(1-0.1)*C15 -> 98.39 | D16: =0.1*C16+(1-0.1)*D15 -> 103.07 | E16: =2*C16-D16+(0.1/(1-0.1))*(C16-D16) -> 93.19 | F16: =0.2*B16+(1-0.2)*F15 -> 95.19 | G16: =0.2*F16+(1-0.2)*G15 -> 97.88 | H16: =2*F16-G16+(0.2/(1-0.2))*(F16-G16) -> 91.83 | I16: =0.3*B16+(1-0.3)*I15 -> 94.36 | J16: =0.3*I16+(1-0.3)*J15 -> 94.78 | K16: =2*I16-J16+(0.3/(1-0.3))*(I16-J16) -> 93.76 | L16: =0.4*B16+(1-0.4)*L15 -> 94.50 | M16: =0.4*L16+(1-0.4)*M15 -> 93.58 | N16: =2*L16-M16+(0.4/(1-0.4))*(L16-M16) -> 96.02 | O16: =0.5*B16+(1-0.5)*O15 -> 95.00 | P16: =0.5*O16+(1-0.5)*P15 -> 93.56 | Q16: =2*O16-P16+(0.5/(1-0.5))*(O16-P16) -> 97.88 | R16: =0.6*B16+(1-0.6)*R15 -> 95.59 | S16: =0.6*R16+(1-0.6)*S15 -> 94.16 | T16: =2*R16-S16+(0.6/(1-0.6))*(R16-S16) -> 99.17 | U16: =0.7*B16+(1-0.7)*U15 -> 96.16 | V16: =0.7*U16+(1-0.7)*V15 -> 95.07 | W16: =2*U16-V16+(0.7/(1-0.7))*(U16-V16) -> 99.79 | X16: =0.8*B16+(1-0.8)*X15 -> 96.61 | Y16: =0.8*X16+(1-0.8)*Y15 -> 96.01 | Z16: =2*X16-Y16+(0.8/(1-0.8))*(X16-Y16) -> 99.63 | AA16: =0.9*B16+(1-0.9)*AA15 -> 96.90 | AB16: =0.9*AA16+(1-0.9)*AB15 -> 96.72 | AC16: =2*AA16-AB16+(0.9/(1-0.9))*(AA16-AB16) -> 98.68
A17: 11 | B17: =Data!C14 -> 87.00 | C17: =0.1*B17+(1-0.1)*C16 -> 97.25 | D17: =0.1*C17+(1-0.1)*D16 -> 102.49 | E17: =2*C17-D17+(0.1/(1-0.1))*(C17-D17) -> 91.43 | F17: =0.2*B17+(1-0.2)*F16 -> 93.55 | G17: =0.2*F17+(1-0.2)*G16 -> 97.02 | H17: =2*F17-G17+(0.2/(1-0.2))*(F17-G17) -> 89.22 | I17: =0.3*B17+(1-0.3)*I16 -> 92.15 | J17: =0.3*I17+(1-0.3)*J16 -> 93.99 | K17: =2*I17-J17+(0.3/(1-0.3))*(I17-J17) -> 89.53 | L17: =0.4*B17+(1-0.4)*L16 -> 91.50 | M17: =0.4*L17+(1-0.4)*M16 -> 92.75 | N17: =2*L17-M17+(0.4/(1-0.4))*(L17-M17) -> 89.41 | O17: =0.5*B17+(1-0.5)*O16 -> 91.00 | P17: =0.5*O17+(1-0.5)*P16 -> 92.28 | Q17: =2*O17-P17+(0.5/(1-0.5))*(O17-P17) -> 88.44 | R17: =0.6*B17+(1-0.6)*R16 -> 90.44 | S17: =0.6*R17+(1-0.6)*S16 -> 91.93 | T17: =2*R17-S17+(0.6/(1-0.6))*(R17-S17) -> 86.71 | U17: =0.7*B17+(1-0.7)*U16 -> 89.75 | V17: =0.7*U17+(1-0.7)*V16 -> 91.34 | W17: =2*U17-V17+(0.7/(1-0.7))*(U17-V17) -> 84.43 | X17: =0.8*B17+(1-0.8)*X16 -> 88.92 | Y17: =0.8*X17+(1-0.8)*Y16 -> 90.34 | Z17: =2*X17-Y17+(0.8/(1-0.8))*(X17-Y17) -> 81.84 | AA17: =0.9*B17+(1-0.9)*AA16 -> 87.99 | AB17: =0.9*AA17+(1-0.9)*AB16 -> 88.86 | AC17: =2*AA17-AB17+(0.9/(1-0.9))*(AA17-AB17) -> 79.26
A18: 12 | B18: =Data!C15 -> 102.00 | C18: =0.1*B18+(1-0.1)*C17 -> 97.73 | D18: =0.1*C18+(1-0.1)*D17 -> 102.01 | E18: =2*C18-D18+(0.1/(1-0.1))*(C18-D18) -> 92.96 | F18: =0.2*B18+(1-0.2)*F17 -> 95.24 | G18: =0.2*F18+(1-0.2)*G17 -> 96.66 | H18: =2*F18-G18+(0.2/(1-0.2))*(F18-G18) -> 93.47 | I18: =0.3*B18+(1-0.3)*I17 -> 95.11 | J18: =0.3*I18+(1-0.3)*J17 -> 94.33 | K18: =2*I18-J18+(0.3/(1-0.3))*(I18-J18) -> 96.22 | L18: =0.4*B18+(1-0.4)*L17 -> 95.70 | M18: =0.4*L18+(1-0.4)*M17 -> 93.93 | N18: =2*L18-M18+(0.4/(1-0.4))*(L18-M18) -> 98.65 | O18: =0.5*B18+(1-0.5)*O17 -> 96.50 | P18: =0.5*O18+(1-0.5)*P17 -> 94.39 | Q18: =2*O18-P18+(0.5/(1-0.5))*(O18-P18) -> 100.72 | R18: =0.6*B18+(1-0.6)*R17 -> 97.38 | S18: =0.6*R18+(1-0.6)*S17 -> 95.20 | T18: =2*R18-S18+(0.6/(1-0.6))*(R18-S18) -> 102.82 | U18: =0.7*B18+(1-0.7)*U17 -> 98.32 | V18: =0.7*U18+(1-0.7)*V17 -> 96.23 | W18: =2*U18-V18+(0.7/(1-0.7))*(U18-V18) -> 105.30 | X18: =0.8*B18+(1-0.8)*X17 -> 99.38 | Y18: =0.8*X18+(1-0.8)*Y17 -> 97.58 | Z18: =2*X18-Y18+(0.8/(1-0.8))*(X18-Y18) -> 108.43 | AA18: =0.9*B18+(1-0.9)*AA17 -> 100.60 | AB18: =0.9*AA18+(1-0.9)*AB17 -> 99.43 | AC18: =2*AA18-AB18+(0.9/(1-0.9))*(AA18-AB18) -> 112.33
A19: 13 | B19: =Data!C16 -> 97.00 | C19: =0.1*B19+(1-0.1)*C18 -> 97.65 | D19: =0.1*C19+(1-0.1)*D18 -> 101.58 | E19: =2*C19-D19+(0.1/(1-0.1))*(C19-D19) -> 93.29 | F19: =0.2*B19+(1-0.2)*F18 -> 95.59 | G19: =0.2*F19+(1-0.2)*G18 -> 96.45 | H19: =2*F19-G19+(0.2/(1-0.2))*(F19-G19) -> 94.53 | I19: =0.3*B19+(1-0.3)*I18 -> 95.67 | J19: =0.3*I19+(1-0.3)*J18 -> 94.73 | K19: =2*I19-J19+(0.3/(1-0.3))*(I19-J19) -> 97.02 | L19: =0.4*B19+(1-0.4)*L18 -> 96.22 | M19: =0.4*L19+(1-0.4)*M18 -> 94.85 | N19: =2*L19-M19+(0.4/(1-0.4))*(L19-M19) -> 98.51 | O19: =0.5*B19+(1-0.5)*O18 -> 96.75 | P19: =0.5*O19+(1-0.5)*P18 -> 95.57 | Q19: =2*O19-P19+(0.5/(1-0.5))*(O19-P19) -> 99.11 | R19: =0.6*B19+(1-0.6)*R18 -> 97.15 | S19: =0.6*R19+(1-0.6)*S18 -> 96.37 | T19: =2*R19-S19+(0.6/(1-0.6))*(R19-S19) -> 99.10 | U19: =0.7*B19+(1-0.7)*U18 -> 97.40 | V19: =0.7*U19+(1-0.7)*V18 -> 97.05 | W19: =2*U19-V19+(0.7/(1-0.7))*(U19-V19) -> 98.56 | X19: =0.8*B19+(1-0.8)*X18 -> 97.48 | Y19: =0.8*X19+(1-0.8)*Y18 -> 97.50 | Z19: =2*X19-Y19+(0.8/(1-0.8))*(X19-Y19) -> 97.38 | AA19: =0.9*B19+(1-0.9)*AA18 -> 97.36 | AB19: =0.9*AA19+(1-0.9)*AB18 -> 97.57 | AC19: =2*AA19-AB19+(0.9/(1-0.9))*(AA19-AB19) -> 95.29
... A30: 24 | B30: =Data!C27 -> 87.00 | C30: =0.1*B30+(1-0.1)*C29 -> 95.27 | D30: =0.1*C30+(1-0.1)*D29 -> 98.19 | E30: =2*C30-D30+(0.1/(1-0.1))*(C30-D30) -> 92.03 | F30: =0.2*B30+(1-0.2)*F29 -> 93.38 | G30: =0.2*F30+(1-0.2)*G29 -> 95.68 | H30: =2*F30-G30+(0.2/(1-0.2))*(F30-G30) -> 90.49 | I30: =0.3*B30+(1-0.3)*I29 -> 91.89 | J30: =0.3*I30+(1-0.3)*J29 -> 95.12 | K30: =2*I30-J30+(0.3/(1-0.3))*(I30-J30) -> 87.27 | L30: =0.4*B30+(1-0.4)*L29 -> 90.36 | M30: =0.4*L30+(1-0.4)*M29 -> 93.93 | N30: =2*L30-M30+(0.4/(1-0.4))*(L30-M30) -> 84.40 | O30: =0.5*B30+(1-0.5)*O29 -> 88.96 | P30: =0.5*O30+(1-0.5)*P29 -> 92.15 | Q30: =2*O30-P30+(0.5/(1-0.5))*(O30-P30) -> 82.58 | R30: =0.6*B30+(1-0.6)*R29 -> 87.84 | S30: =0.6*R30+(1-0.6)*S29 -> 90.14 | T30: =2*R30-S30+(0.6/(1-0.6))*(R30-S30) -> 82.08 | U30: =0.7*B30+(1-0.7)*U29 -> 87.06 | V30: =0.7*U30+(1-0.7)*V29 -> 88.30 | W30: =2*U30-V30+(0.7/(1-0.7))*(U30-V30) -> 82.95 | X30: =0.8*B30+(1-0.8)*X29 -> 86.67 | Y30: =0.8*X30+(1-0.8)*Y29 -> 86.99 | Z30: =2*X30-Y30+(0.8/(1-0.8))*(X30-Y30) -> 85.08 | AA30: =0.9*B30+(1-0.9)*AA29 -> 86.66 | AB30: =0.9*AA30+(1-0.9)*AB29 -> 86.50 | AC30: =2*AA30-AB30+(0.9/(1-0.9))*(AA30-AB30) -> 88.21
B32: alpha -> | E32: 0.1 | H32: 0.2 | K32: 0.3 | N32: 0.4 | Q32: 0.5 | T32: 0.6 | W32: 0.7 | Z32: 0.8 | AC32: 0.9
B33: MSD | E33: =SUMPRODUCT((B9:B30-E8:E29)^2)/COUNT(E8:E29) -> 63.522 | H33: =SUMPRODUCT((B9:B30-H8:H29)^2)/COUNT(H8:H29) -> 66.392 | K33: =SUMPRODUCT((B9:B30-K8:K29)^2)/COUNT(K8:K29) -> 75.119 | N33: =SUMPRODUCT((B9:B30-N8:N29)^2)/COUNT(N8:N29) -> 88.048 | Q33: =SUMPRODUCT((B9:B30-Q8:Q29)^2)/COUNT(Q8:Q29) -> 104.989 | T33: =SUMPRODUCT((B9:B30-T8:T29)^2)/COUNT(T8:T29) -> 126.055 | W33: =SUMPRODUCT((B9:B30-W8:W29)^2)/COUNT(W8:W29) -> 151.733 | Z33: =SUMPRODUCT((B9:B30-Z8:Z29)^2)/COUNT(Z8:Z29) -> 183.135 | AC33: =SUMPRODUCT((B9:B30-AC8:AC29)^2)/COUNT(AC8:AC29) -> 222.630
B34: MAD | E34: =SUMPRODUCT(ABS(B9:B30-E8:E29))/COUNT(E8:E29) -> 6.898 | H34: =SUMPRODUCT(ABS(B9:B30-H8:H29))/COUNT(H8:H29) -> 6.703 | K34: =SUMPRODUCT(ABS(B9:B30-K8:K29))/COUNT(K8:K29) -> 7.112 | N34: =SUMPRODUCT(ABS(B9:B30-N8:N29))/COUNT(N8:N29) -> 7.867 | Q34: =SUMPRODUCT(ABS(B9:B30-Q8:Q29))/COUNT(Q8:Q29) -> 8.983 | T34: =SUMPRODUCT(ABS(B9:B30-T8:T29))/COUNT(T8:T29) -> 9.873 | W34: =SUMPRODUCT(ABS(B9:B30-W8:W29))/COUNT(W8:W29) -> 10.913 | Z34: =SUMPRODUCT(ABS(B9:B30-Z8:Z29))/COUNT(Z8:Z29) -> 11.736 | AC34: =SUMPRODUCT(ABS(B9:B30-AC8:AC29))/COUNT(AC8:AC29) -> 12.593
B35: MAPE (%) | E35: =SUMPRODUCT(ABS(B9:B30-E8:E29)/B9:B30)/COUNT(E8:E29)*100 -> 7.34 | H35: =SUMPRODUCT(ABS(B9:B30-H8:H29)/B9:B30)/COUNT(H8:H29)*100 -> 7.11 | K35: =SUMPRODUCT(ABS(B9:B30-K8:K29)/B9:B30)/COUNT(K8:K29)*100 -> 7.55 | N35: =SUMPRODUCT(ABS(B9:B30-N8:N29)/B9:B30)/COUNT(N8:N29)*100 -> 8.34 | Q35: =SUMPRODUCT(ABS(B9:B30-Q8:Q29)/B9:B30)/COUNT(Q8:Q29)*100 -> 9.54 | T35: =SUMPRODUCT(ABS(B9:B30-T8:T29)/B9:B30)/COUNT(T8:T29)*100 -> 10.49 | W35: =SUMPRODUCT(ABS(B9:B30-W8:W29)/B9:B30)/COUNT(W8:W29)*100 -> 11.58 | Z35: =SUMPRODUCT(ABS(B9:B30-Z8:Z29)/B9:B30)/COUNT(Z8:Z29)*100 -> 12.43 | AC35: =SUMPRODUCT(ABS(B9:B30-AC8:AC29)/B9:B30)/COUNT(AC8:AC29)*100 -> 13.29
A36: Alpha terbaik: | B36: {=INDEX(E32:AC32,MATCH(MIN(E33:AC33),E33:AC33,0))} -> 0.1
A37: MSD terbaik: | B37: =MIN(E33:AC33) -> 63.522
A40: SALES (data + NIM)
A41: t | B41: Actual | C41: S' (α=0.1) | D41: S'' (α=0.1) | E41: F (α=0.1) | F41: S' (α=0.2) | G41: S'' (α=0.2) | H41: F (α=0.2) | I41: S' (α=0.3) | J41: S'' (α=0.3) | K41: F (α=0.3) | L41: S' (α=0.4) | M41: S'' (α=0.4) | N41: F (α=0.4) | O41: S' (α=0.5) | P41: S'' (α=0.5) | Q41: F (α=0.5) | R41: S' (α=0.6) | S41: S'' (α=0.6) | T41: F (α=0.6) | U41: S' (α=0.7) | V41: S'' (α=0.7) | W41: F (α=0.7) | X41: S' (α=0.8) | Y41: S'' (α=0.8) | Z41: F (α=0.8) | AA41: S' (α=0.9) | AB41: S'' (α=0.9) | AC41: F (α=0.9)
A42: 1 | B42: =Data!E4 -> 174.80 | C42: =B42 -> 174.80 | D42: =B42 -> 174.80 | E42: =2*C42-D42+(0.1/(1-0.1))*(C42-D42) -> 174.80 | F42: =B42 -> 174.80 | G42: =B42 -> 174.80 | H42: =2*F42-G42+(0.2/(1-0.2))*(F42-G42) -> 174.80 | I42: =B42 -> 174.80 | J42: =B42 -> 174.80 | K42: =2*I42-J42+(0.3/(1-0.3))*(I42-J42) -> 174.80 | L42: =B42 -> 174.80 | M42: =B42 -> 174.80 | N42: =2*L42-M42+(0.4/(1-0.4))*(L42-M42) -> 174.80 | O42: =B42 -> 174.80 | P42: =B42 -> 174.80 | Q42: =2*O42-P42+(0.5/(1-0.5))*(O42-P42) -> 174.80 | R42: =B42 -> 174.80 | S42: =B42 -> 174.80 | T42: =2*R42-S42+(0.6/(1-0.6))*(R42-S42) -> 174.80 | U42: =B42 -> 174.80 | V42: =B42 -> 174.80 | W42: =2*U42-V42+(0.7/(1-0.7))*(U42-V42) -> 174.80 | X42: =B42 -> 174.80 | Y42: =B42 -> 174.80 | Z42: =2*X42-Y42+(0.8/(1-0.8))*(X42-Y42) -> 174.80 | AA42: =B42 -> 174.80 | AB42: =B42 -> 174.80 | AC42: =2*AA42-AB42+(0.9/(1-0.9))*(AA42-AB42) -> 174.80
A43: 2 | B43: =Data!E5 -> 161.20 | C43: =0.1*B43+(1-0.1)*C42 -> 173.44 | D43: =0.1*C43+(1-0.1)*D42 -> 174.66 | E43: =2*C43-D43+(0.1/(1-0.1))*(C43-D43) -> 172.08 | F43: =0.2*B43+(1-0.2)*F42 -> 172.08 | G43: =0.2*F43+(1-0.2)*G42 -> 174.26 | H43: =2*F43-G43+(0.2/(1-0.2))*(F43-G43) -> 169.36 | I43: =0.3*B43+(1-0.3)*I42 -> 170.72 | J43: =0.3*I43+(1-0.3)*J42 -> 173.58 | K43: =2*I43-J43+(0.3/(1-0.3))*(I43-J43) -> 166.64 | L43: =0.4*B43+(1-0.4)*L42 -> 169.36 | M43: =0.4*L43+(1-0.4)*M42 -> 172.62 | N43: =2*L43-M43+(0.4/(1-0.4))*(L43-M43) -> 163.92 | O43: =0.5*B43+(1-0.5)*O42 -> 168.00 | P43: =0.5*O43+(1-0.5)*P42 -> 171.40 | Q43: =2*O43-P43+(0.5/(1-0.5))*(O43-P43) -> 161.20 | R43: =0.6*B43+(1-0.6)*R42 -> 166.64 | S43: =0.6*R43+(1-0.6)*S42 -> 169.90 | T43: =2*R43-S43+(0.6/(1-0.6))*(R43-S43) -> 158.48 | U43: =0.7*B43+(1-0.7)*U42 -> 165.28 | V43: =0.7*U43+(1-0.7)*V42 -> 168.14 | W43: =2*U43-V43+(0.7/(1-0.7))*(U43-V43) -> 155.76 | X43: =0.8*B43+(1-0.8)*X42 -> 163.92 | Y43: =0.8*X43+(1-0.8)*Y42 -> 166.10 | Z43: =2*X43-Y43+(0.8/(1-0.8))*(X43-Y43) -> 153.04 | AA43: =0.9*B43+(1-0.9)*AA42 -> 162.56 | AB43: =0.9*AA43+(1-0.9)*AB42 -> 163.78 | AC43: =2*AA43-AB43+(0.9/(1-0.9))*(AA43-AB43) -> 150.32
A44: 3 | B44: =Data!E6 -> 166.50 | C44: =0.1*B44+(1-0.1)*C43 -> 172.75 | D44: =0.1*C44+(1-0.1)*D43 -> 174.47 | E44: =2*C44-D44+(0.1/(1-0.1))*(C44-D44) -> 170.83 | F44: =0.2*B44+(1-0.2)*F43 -> 170.96 | G44: =0.2*F44+(1-0.2)*G43 -> 173.60 | H44: =2*F44-G44+(0.2/(1-0.2))*(F44-G44) -> 167.67 | I44: =0.3*B44+(1-0.3)*I43 -> 169.45 | J44: =0.3*I44+(1-0.3)*J43 -> 172.34 | K44: =2*I44-J44+(0.3/(1-0.3))*(I44-J44) -> 165.33 | L44: =0.4*B44+(1-0.4)*L43 -> 168.22 | M44: =0.4*L44+(1-0.4)*M43 -> 170.86 | N44: =2*L44-M44+(0.4/(1-0.4))*(L44-M44) -> 163.81 | O44: =0.5*B44+(1-0.5)*O43 -> 167.25 | P44: =0.5*O44+(1-0.5)*P43 -> 169.33 | Q44: =2*O44-P44+(0.5/(1-0.5))*(O44-P44) -> 163.10 | R44: =0.6*B44+(1-0.6)*R43 -> 166.56 | S44: =0.6*R44+(1-0.6)*S43 -> 167.90 | T44: =2*R44-S44+(0.6/(1-0.6))*(R44-S44) -> 163.21 | U44: =0.7*B44+(1-0.7)*U43 -> 166.13 | V44: =0.7*U44+(1-0.7)*V43 -> 166.73 | W44: =2*U44-V44+(0.7/(1-0.7))*(U44-V44) -> 164.13 | X44: =0.8*B44+(1-0.8)*X43 -> 165.98 | Y44: =0.8*X44+(1-0.8)*Y43 -> 166.01 | Z44: =2*X44-Y44+(0.8/(1-0.8))*(X44-Y44) -> 165.87 | AA44: =0.9*B44+(1-0.9)*AA43 -> 166.11 | AB44: =0.9*AA44+(1-0.9)*AB43 -> 165.87 | AC44: =2*AA44-AB44+(0.9/(1-0.9))*(AA44-AB44) -> 168.43
A45: 4 | B45: =Data!E7 -> 165.00 | C45: =0.1*B45+(1-0.1)*C44 -> 171.97 | D45: =0.1*C45+(1-0.1)*D44 -> 174.22 | E45: =2*C45-D45+(0.1/(1-0.1))*(C45-D45) -> 169.47 | F45: =0.2*B45+(1-0.2)*F44 -> 169.77 | G45: =0.2*F45+(1-0.2)*G44 -> 172.83 | H45: =2*F45-G45+(0.2/(1-0.2))*(F45-G45) -> 165.94 | I45: =0.3*B45+(1-0.3)*I44 -> 168.12 | J45: =0.3*I45+(1-0.3)*J44 -> 171.07 | K45: =2*I45-J45+(0.3/(1-0.3))*(I45-J45) -> 163.90 | L45: =0.4*B45+(1-0.4)*L44 -> 166.93 | M45: =0.4*L45+(1-0.4)*M44 -> 169.29 | N45: =2*L45-M45+(0.4/(1-0.4))*(L45-M45) -> 163.00 | O45: =0.5*B45+(1-0.5)*O44 -> 166.13 | P45: =0.5*O45+(1-0.5)*P44 -> 167.73 | Q45: =2*O45-P45+(0.5/(1-0.5))*(O45-P45) -> 162.93 | R45: =0.6*B45+(1-0.6)*R44 -> 165.62 | S45: =0.6*R45+(1-0.6)*S44 -> 166.53 | T45: =2*R45-S45+(0.6/(1-0.6))*(R45-S45) -> 163.35 | U45: =0.7*B45+(1-0.7)*U44 -> 165.34 | V45: =0.7*U45+(1-0.7)*V44 -> 165.76 | W45: =2*U45-V45+(0.7/(1-0.7))*(U45-V45) -> 163.95 | X45: =0.8*B45+(1-0.8)*X44 -> 165.20 | Y45: =0.8*X45+(1-0.8)*Y44 -> 165.36 | Z45: =2*X45-Y45+(0.8/(1-0.8))*(X45-Y45) -> 164.39 | AA45: =0.9*B45+(1-0.9)*AA44 -> 165.11 | AB45: =0.9*AA45+(1-0.9)*AB44 -> 165.19 | AC45: =2*AA45-AB45+(0.9/(1-0.9))*(AA45-AB45) -> 164.35
A46: 5 | B46: =Data!E8 -> 170.10 | C46: =0.1*B46+(1-0.1)*C45 -> 171.78 | D46: =0.1*C46+(1-0.1)*D45 -> 173.98 | E46: =2*C46-D46+(0.1/(1-0.1))*(C46-D46) -> 169.35 | F46: =0.2*B46+(1-0.2)*F45 -> 169.84 | G46: =0.2*F46+(1-0.2)*G45 -> 172.23 | H46: =2*F46-G46+(0.2/(1-0.2))*(F46-G46) -> 166.84 | I46: =0.3*B46+(1-0.3)*I45 -> 168.71 | J46: =0.3*I46+(1-0.3)*J45 -> 170.36 | K46: =2*I46-J46+(0.3/(1-0.3))*(I46-J46) -> 166.35 | L46: =0.4*B46+(1-0.4)*L45 -> 168.20 | M46: =0.4*L46+(1-0.4)*M45 -> 168.85 | N46: =2*L46-M46+(0.4/(1-0.4))*(L46-M46) -> 167.11 | O46: =0.5*B46+(1-0.5)*O45 -> 168.11 | P46: =0.5*O46+(1-0.5)*P45 -> 167.92 | Q46: =2*O46-P46+(0.5/(1-0.5))*(O46-P46) -> 168.50 | R46: =0.6*B46+(1-0.6)*R45 -> 168.31 | S46: =0.6*R46+(1-0.6)*S45 -> 167.60 | T46: =2*R46-S46+(0.6/(1-0.6))*(R46-S46) -> 170.09 | U46: =0.7*B46+(1-0.7)*U45 -> 168.67 | V46: =0.7*U46+(1-0.7)*V45 -> 167.80 | W46: =2*U46-V46+(0.7/(1-0.7))*(U46-V46) -> 171.59 | X46: =0.8*B46+(1-0.8)*X45 -> 169.12 | Y46: =0.8*X46+(1-0.8)*Y45 -> 168.37 | Z46: =2*X46-Y46+(0.8/(1-0.8))*(X46-Y46) -> 172.88 | AA46: =0.9*B46+(1-0.9)*AA45 -> 169.60 | AB46: =0.9*AA46+(1-0.9)*AB45 -> 169.16 | AC46: =2*AA46-AB46+(0.9/(1-0.9))*(AA46-AB46) -> 174.02
A47: 6 | B47: =Data!E9 -> 165.90 | C47: =0.1*B47+(1-0.1)*C46 -> 171.20 | D47: =0.1*C47+(1-0.1)*D46 -> 173.70 | E47: =2*C47-D47+(0.1/(1-0.1))*(C47-D47) -> 168.41 | F47: =0.2*B47+(1-0.2)*F46 -> 169.05 | G47: =0.2*F47+(1-0.2)*G46 -> 171.60 | H47: =2*F47-G47+(0.2/(1-0.2))*(F47-G47) -> 165.87 | I47: =0.3*B47+(1-0.3)*I46 -> 167.87 | J47: =0.3*I47+(1-0.3)*J46 -> 169.62 | K47: =2*I47-J47+(0.3/(1-0.3))*(I47-J47) -> 165.37 | L47: =0.4*B47+(1-0.4)*L46 -> 167.28 | M47: =0.4*L47+(1-0.4)*M46 -> 168.22 | N47: =2*L47-M47+(0.4/(1-0.4))*(L47-M47) -> 165.71 | O47: =0.5*B47+(1-0.5)*O46 -> 167.01 | P47: =0.5*O47+(1-0.5)*P46 -> 167.46 | Q47: =2*O47-P47+(0.5/(1-0.5))*(O47-P47) -> 166.09 | R47: =0.6*B47+(1-0.6)*R46 -> 166.86 | S47: =0.6*R47+(1-0.6)*S46 -> 167.16 | T47: =2*R47-S47+(0.6/(1-0.6))*(R47-S47) -> 166.13 | U47: =0.7*B47+(1-0.7)*U46 -> 166.73 | V47: =0.7*U47+(1-0.7)*V46 -> 167.05 | W47: =2*U47-V47+(0.7/(1-0.7))*(U47-V47) -> 165.67 | X47: =0.8*B47+(1-0.8)*X46 -> 166.54 | Y47: =0.8*X47+(1-0.8)*Y46 -> 166.91 | Z47: =2*X47-Y47+(0.8/(1-0.8))*(X47-Y47) -> 164.72 | AA47: =0.9*B47+(1-0.9)*AA46 -> 166.27 | AB47: =0.9*AA47+(1-0.9)*AB46 -> 166.56 | AC47: =2*AA47-AB47+(0.9/(1-0.9))*(AA47-AB47) -> 163.38
A48: 7 | B48: =Data!E10 -> 161.90 | C48: =0.1*B48+(1-0.1)*C47 -> 170.27 | D48: =0.1*C48+(1-0.1)*D47 -> 173.36 | E48: =2*C48-D48+(0.1/(1-0.1))*(C48-D48) -> 166.83 | F48: =0.2*B48+(1-0.2)*F47 -> 167.62 | G48: =0.2*F48+(1-0.2)*G47 -> 170.80 | H48: =2*F48-G48+(0.2/(1-0.2))*(F48-G48) -> 163.64 | I48: =0.3*B48+(1-0.3)*I47 -> 166.08 | J48: =0.3*I48+(1-0.3)*J47 -> 168.55 | K48: =2*I48-J48+(0.3/(1-0.3))*(I48-J48) -> 162.54 | L48: =0.4*B48+(1-0.4)*L47 -> 165.13 | M48: =0.4*L48+(1-0.4)*M47 -> 166.98 | N48: =2*L48-M48+(0.4/(1-0.4))*(L48-M48) -> 162.03 | O48: =0.5*B48+(1-0.5)*O47 -> 164.45 | P48: =0.5*O48+(1-0.5)*P47 -> 165.96 | Q48: =2*O48-P48+(0.5/(1-0.5))*(O48-P48) -> 161.44 | R48: =0.6*B48+(1-0.6)*R47 -> 163.89 | S48: =0.6*R48+(1-0.6)*S47 -> 165.19 | T48: =2*R48-S48+(0.6/(1-0.6))*(R48-S48) -> 160.61 | U48: =0.7*B48+(1-0.7)*U47 -> 163.35 | V48: =0.7*U48+(1-0.7)*V47 -> 164.46 | W48: =2*U48-V48+(0.7/(1-0.7))*(U48-V48) -> 159.65 | X48: =0.8*B48+(1-0.8)*X47 -> 162.83 | Y48: =0.8*X48+(1-0.8)*Y47 -> 163.64 | Z48: =2*X48-Y48+(0.8/(1-0.8))*(X48-Y48) -> 158.75 | AA48: =0.9*B48+(1-0.9)*AA47 -> 162.34 | AB48: =0.9*AA48+(1-0.9)*AB47 -> 162.76 | AC48: =2*AA48-AB48+(0.9/(1-0.9))*(AA48-AB48) -> 158.11
A49: 8 | B49: =Data!E11 -> 163.10 | C49: =0.1*B49+(1-0.1)*C48 -> 169.55 | D49: =0.1*C49+(1-0.1)*D48 -> 172.98 | E49: =2*C49-D49+(0.1/(1-0.1))*(C49-D49) -> 165.74 | F49: =0.2*B49+(1-0.2)*F48 -> 166.72 | G49: =0.2*F49+(1-0.2)*G48 -> 169.98 | H49: =2*F49-G49+(0.2/(1-0.2))*(F49-G49) -> 162.63 | I49: =0.3*B49+(1-0.3)*I48 -> 165.18 | J49: =0.3*I49+(1-0.3)*J48 -> 167.54 | K49: =2*I49-J49+(0.3/(1-0.3))*(I49-J49) -> 161.81 | L49: =0.4*B49+(1-0.4)*L48 -> 164.32 | M49: =0.4*L49+(1-0.4)*M48 -> 165.92 | N49: =2*L49-M49+(0.4/(1-0.4))*(L49-M49) -> 161.65 | O49: =0.5*B49+(1-0.5)*O48 -> 163.78 | P49: =0.5*O49+(1-0.5)*P48 -> 164.87 | Q49: =2*O49-P49+(0.5/(1-0.5))*(O49-P49) -> 161.60 | R49: =0.6*B49+(1-0.6)*R48 -> 163.41 | S49: =0.6*R49+(1-0.6)*S48 -> 164.13 | T49: =2*R49-S49+(0.6/(1-0.6))*(R49-S49) -> 161.63 | U49: =0.7*B49+(1-0.7)*U48 -> 163.17 | V49: =0.7*U49+(1-0.7)*V48 -> 163.56 | W49: =2*U49-V49+(0.7/(1-0.7))*(U49-V49) -> 161.89 | X49: =0.8*B49+(1-0.8)*X48 -> 163.05 | Y49: =0.8*X49+(1-0.8)*Y48 -> 163.17 | Z49: =2*X49-Y49+(0.8/(1-0.8))*(X49-Y49) -> 162.45 | AA49: =0.9*B49+(1-0.9)*AA48 -> 163.02 | AB49: =0.9*AA49+(1-0.9)*AB48 -> 163.00 | AC49: =2*AA49-AB49+(0.9/(1-0.9))*(AA49-AB49) -> 163.29
A50: 9 | B50: =Data!E12 -> 168.40 | C50: =0.1*B50+(1-0.1)*C49 -> 169.43 | D50: =0.1*C50+(1-0.1)*D49 -> 172.62 | E50: =2*C50-D50+(0.1/(1-0.1))*(C50-D50) -> 165.89 | F50: =0.2*B50+(1-0.2)*F49 -> 167.05 | G50: =0.2*F50+(1-0.2)*G49 -> 169.40 | H50: =2*F50-G50+(0.2/(1-0.2))*(F50-G50) -> 164.12 | I50: =0.3*B50+(1-0.3)*I49 -> 166.15 | J50: =0.3*I50+(1-0.3)*J49 -> 167.13 | K50: =2*I50-J50+(0.3/(1-0.3))*(I50-J50) -> 164.75 | L50: =0.4*B50+(1-0.4)*L49 -> 165.95 | M50: =0.4*L50+(1-0.4)*M49 -> 165.93 | N50: =2*L50-M50+(0.4/(1-0.4))*(L50-M50) -> 165.98 | O50: =0.5*B50+(1-0.5)*O49 -> 166.09 | P50: =0.5*O50+(1-0.5)*P49 -> 165.48 | Q50: =2*O50-P50+(0.5/(1-0.5))*(O50-P50) -> 167.31 | R50: =0.6*B50+(1-0.6)*R49 -> 166.41 | S50: =0.6*R50+(1-0.6)*S49 -> 165.49 | T50: =2*R50-S50+(0.6/(1-0.6))*(R50-S50) -> 168.69 | U50: =0.7*B50+(1-0.7)*U49 -> 166.83 | V50: =0.7*U50+(1-0.7)*V49 -> 165.85 | W50: =2*U50-V50+(0.7/(1-0.7))*(U50-V50) -> 170.10 | X50: =0.8*B50+(1-0.8)*X49 -> 167.33 | Y50: =0.8*X50+(1-0.8)*Y49 -> 166.50 | Z50: =2*X50-Y50+(0.8/(1-0.8))*(X50-Y50) -> 171.49 | AA50: =0.9*B50+(1-0.9)*AA49 -> 167.86 | AB50: =0.9*AA50+(1-0.9)*AB49 -> 167.38 | AC50: =2*AA50-AB50+(0.9/(1-0.9))*(AA50-AB50) -> 172.73
A51: 10 | B51: =Data!E13 -> 168.30 | C51: =0.1*B51+(1-0.1)*C50 -> 169.32 | D51: =0.1*C51+(1-0.1)*D50 -> 172.29 | E51: =2*C51-D51+(0.1/(1-0.1))*(C51-D51) -> 166.02 | F51: =0.2*B51+(1-0.2)*F50 -> 167.30 | G51: =0.2*F51+(1-0.2)*G50 -> 168.98 | H51: =2*F51-G51+(0.2/(1-0.2))*(F51-G51) -> 165.21 | I51: =0.3*B51+(1-0.3)*I50 -> 166.79 | J51: =0.3*I51+(1-0.3)*J50 -> 167.03 | K51: =2*I51-J51+(0.3/(1-0.3))*(I51-J51) -> 166.46 | L51: =0.4*B51+(1-0.4)*L50 -> 166.89 | M51: =0.4*L51+(1-0.4)*M50 -> 166.31 | N51: =2*L51-M51+(0.4/(1-0.4))*(L51-M51) -> 167.85 | O51: =0.5*B51+(1-0.5)*O50 -> 167.19 | P51: =0.5*O51+(1-0.5)*P50 -> 166.34 | Q51: =2*O51-P51+(0.5/(1-0.5))*(O51-P51) -> 168.91 | R51: =0.6*B51+(1-0.6)*R50 -> 167.54 | S51: =0.6*R51+(1-0.6)*S50 -> 166.72 | T51: =2*R51-S51+(0.6/(1-0.6))*(R51-S51) -> 169.59 | U51: =0.7*B51+(1-0.7)*U50 -> 167.86 | V51: =0.7*U51+(1-0.7)*V50 -> 167.26 | W51: =2*U51-V51+(0.7/(1-0.7))*(U51-V51) -> 169.87 | X51: =0.8*B51+(1-0.8)*X50 -> 168.11 | Y51: =0.8*X51+(1-0.8)*Y50 -> 167.78 | Z51: =2*X51-Y51+(0.8/(1-0.8))*(X51-Y51) -> 169.72 | AA51: =0.9*B51+(1-0.9)*AA50 -> 168.26 | AB51: =0.9*AA51+(1-0.9)*AB50 -> 168.17 | AC51: =2*AA51-AB51+(0.9/(1-0.9))*(AA51-AB51) -> 169.14
A52: 11 | B52: =Data!E14 -> 163.90 | C52: =0.1*B52+(1-0.1)*C51 -> 168.78 | D52: =0.1*C52+(1-0.1)*D51 -> 171.94 | E52: =2*C52-D52+(0.1/(1-0.1))*(C52-D52) -> 165.27 | F52: =0.2*B52+(1-0.2)*F51 -> 166.62 | G52: =0.2*F52+(1-0.2)*G51 -> 168.51 | H52: =2*F52-G52+(0.2/(1-0.2))*(F52-G52) -> 164.26 | I52: =0.3*B52+(1-0.3)*I51 -> 165.93 | J52: =0.3*I52+(1-0.3)*J51 -> 166.70 | K52: =2*I52-J52+(0.3/(1-0.3))*(I52-J52) -> 164.83 | L52: =0.4*B52+(1-0.4)*L51 -> 165.69 | M52: =0.4*L52+(1-0.4)*M51 -> 166.07 | N52: =2*L52-M52+(0.4/(1-0.4))*(L52-M52) -> 165.07 | O52: =0.5*B52+(1-0.5)*O51 -> 165.55 | P52: =0.5*O52+(1-0.5)*P51 -> 165.94 | Q52: =2*O52-P52+(0.5/(1-0.5))*(O52-P52) -> 164.76 | R52: =0.6*B52+(1-0.6)*R51 -> 165.36 | S52: =0.6*R52+(1-0.6)*S51 -> 165.90 | T52: =2*R52-S52+(0.6/(1-0.6))*(R52-S52) -> 163.99 | U52: =0.7*B52+(1-0.7)*U51 -> 165.09 | V52: =0.7*U52+(1-0.7)*V51 -> 165.74 | W52: =2*U52-V52+(0.7/(1-0.7))*(U52-V52) -> 162.92 | X52: =0.8*B52+(1-0.8)*X51 -> 164.74 | Y52: =0.8*X52+(1-0.8)*Y51 -> 165.35 | Z52: =2*X52-Y52+(0.8/(1-0.8))*(X52-Y52) -> 161.70 | AA52: =0.9*B52+(1-0.9)*AA51 -> 164.34 | AB52: =0.9*AA52+(1-0.9)*AB51 -> 164.72 | AC52: =2*AA52-AB52+(0.9/(1-0.9))*(AA52-AB52) -> 160.50
A53: 12 | B53: =Data!E15 -> 172.60 | C53: =0.1*B53+(1-0.1)*C52 -> 169.16 | D53: =0.1*C53+(1-0.1)*D52 -> 171.66 | E53: =2*C53-D53+(0.1/(1-0.1))*(C53-D53) -> 166.38 | F53: =0.2*B53+(1-0.2)*F52 -> 167.82 | G53: =0.2*F53+(1-0.2)*G52 -> 168.37 | H53: =2*F53-G53+(0.2/(1-0.2))*(F53-G53) -> 167.13 | I53: =0.3*B53+(1-0.3)*I52 -> 167.93 | J53: =0.3*I53+(1-0.3)*J52 -> 167.07 | K53: =2*I53-J53+(0.3/(1-0.3))*(I53-J53) -> 169.16 | L53: =0.4*B53+(1-0.4)*L52 -> 168.46 | M53: =0.4*L53+(1-0.4)*M52 -> 167.02 | N53: =2*L53-M53+(0.4/(1-0.4))*(L53-M53) -> 170.85 | O53: =0.5*B53+(1-0.5)*O52 -> 169.07 | P53: =0.5*O53+(1-0.5)*P52 -> 167.51 | Q53: =2*O53-P53+(0.5/(1-0.5))*(O53-P53) -> 172.21 | R53: =0.6*B53+(1-0.6)*R52 -> 169.70 | S53: =0.6*R53+(1-0.6)*S52 -> 168.18 | T53: =2*R53-S53+(0.6/(1-0.6))*(R53-S53) -> 173.50 | U53: =0.7*B53+(1-0.7)*U52 -> 170.35 | V53: =0.7*U53+(1-0.7)*V52 -> 168.96 | W53: =2*U53-V53+(0.7/(1-0.7))*(U53-V53) -> 174.95 | X53: =0.8*B53+(1-0.8)*X52 -> 171.03 | Y53: =0.8*X53+(1-0.8)*Y52 -> 169.89 | Z53: =2*X53-Y53+(0.8/(1-0.8))*(X53-Y53) -> 176.71 | AA53: =0.9*B53+(1-0.9)*AA52 -> 171.77 | AB53: =0.9*AA53+(1-0.9)*AB52 -> 171.07 | AC53: =2*AA53-AB53+(0.9/(1-0.9))*(AA53-AB53) -> 178.83
A54: 13 | B54: =Data!E16 -> 173.40 | C54: =0.1*B54+(1-0.1)*C53 -> 169.59 | D54: =0.1*C54+(1-0.1)*D53 -> 171.45 | E54: =2*C54-D54+(0.1/(1-0.1))*(C54-D54) -> 167.51 | F54: =0.2*B54+(1-0.2)*F53 -> 168.93 | G54: =0.2*F54+(1-0.2)*G53 -> 168.48 | H54: =2*F54-G54+(0.2/(1-0.2))*(F54-G54) -> 169.50 | I54: =0.3*B54+(1-0.3)*I53 -> 169.57 | J54: =0.3*I54+(1-0.3)*J53 -> 167.82 | K54: =2*I54-J54+(0.3/(1-0.3))*(I54-J54) -> 172.07 | L54: =0.4*B54+(1-0.4)*L53 -> 170.43 | M54: =0.4*L54+(1-0.4)*M53 -> 168.39 | N54: =2*L54-M54+(0.4/(1-0.4))*(L54-M54) -> 173.85 | O54: =0.5*B54+(1-0.5)*O53 -> 171.24 | P54: =0.5*O54+(1-0.5)*P53 -> 169.37 | Q54: =2*O54-P54+(0.5/(1-0.5))*(O54-P54) -> 174.97 | R54: =0.6*B54+(1-0.6)*R53 -> 171.92 | S54: =0.6*R54+(1-0.6)*S53 -> 170.43 | T54: =2*R54-S54+(0.6/(1-0.6))*(R54-S54) -> 175.66 | U54: =0.7*B54+(1-0.7)*U53 -> 172.48 | V54: =0.7*U54+(1-0.7)*V53 -> 171.43 | W54: =2*U54-V54+(0.7/(1-0.7))*(U54-V54) -> 176.00 | X54: =0.8*B54+(1-0.8)*X53 -> 172.93 | Y54: =0.8*X54+(1-0.8)*Y53 -> 172.32 | Z54: =2*X54-Y54+(0.8/(1-0.8))*(X54-Y54) -> 175.96 | AA54: =0.9*B54+(1-0.9)*AA53 -> 173.24 | AB54: =0.9*AA54+(1-0.9)*AB53 -> 173.02 | AC54: =2*AA54-AB54+(0.9/(1-0.9))*(AA54-AB54) -> 175.41
